Workbook

Sheet 首页
C4: TGFW V60R001C00 二层转发特性测试用例
C15: 拟定 | D15: 李源源 | F15: 日期 | G15: 44524
C17: 审核 | F17: 日期 | G17: XXXX/XX/XX
C19: 批准 | F19: 日期
E23: 修订记录
C25: 日期 | D25: 修订版本 | E25: 修改记录 | I25: 修改人
C26: 44524 | D26: V1.0 | E26: 初稿输出 | I26: 李源源

Sheet 测试点分析
A1: 四级目录 | B1: 五级目录 | C1: 测试点 | D1: 测试设计方法 | E1: 适用场景 | F1: 用例规模（个） | G1: 测试数据
A2: vlan转发
B3: mac转发
C4: 根据MAC地址转发表转发业务测试 | D4: 流程图 | F4: 3 | G4: MAC地址转发表
C5: 广播和未知单播转发测试 | D5: 直接分析 | F5: 1 | G5: 广播、未知单播
C6: L3子接口不进行二层转发测试 | D6: 直接分析 | F6: 1 | G6: L3子接口不能进行二层转发
C7: 聚合口进行二层转发测试 | D7: 直接分析 | F7: 1 | G7: 二层聚合口
C8: 二层转发与策略路由的耦合 | D8: 直接分析 | F8: 1 | G8: 策略路由对二层转发报文不生效
C9: 二层转发与ACL的耦合 | D9: 直接分析 | F9: 1 | G9: 二层转发报文匹配ACL
C10: MAC转发表最大数量下的二层转发测试 | D10: 直接分析 | F10: 1 | G10: MAC转发表达到最大数量后业务转发
B11: vlan隔离
C12: 不同模式下VLAN配置测试 | D12: 等价类划分&数据组合 | F12: 4 | G12: access和trunk模式下的vlan配置
C13: access入方向对二层报文的处理测试 | D13: 直接分析 | F13: 3 | G13: access入方向对带vlan和不带vlan报文的处理
C14: access出方向对二层报文的处理测试 | D14: 直接分析 | F14: 3 | G14: access出方向对带vlan和不带vlan报文的处理
C15: trunk入方向对二层报文的处理测试 | D15: 直接分析 | F15: 3 | G15: trunk入方向对带vlan和不带vlan报文的处理
C16: trunk出方向对二层报文的处理测试 | D16: 直接分析 | F16: 3 | G16: trunk出方向对带vlan和不带vlan报文的处理
C17: access端口之间报文转发测试 | D17: 直接分析 | F17: 1 | G17: access端口之间报文转发
C18: trunk端口之间报文转发测试 | D18: 直接分析 | F18: 2 | G18: trunk端口之间报文转发
C19: access和trunk之间报文转发测试 | D19: 直接分析 | F19: 2 | G19: access和trunk之间报文转发
C20: 多层vlan报文转发测试 | D20: 直接分析 | F20: 3 | G20: access和trunk模式下的多层vlan报文转发
C21: 特殊vlan报文转发测试 | D21: 直接分析 | F21: 1 | G21: vlan为0和4095的报文转发
C22: 修改二层接口tag属性对报文转发的影响测试 | D22: 直接分析 | F22: 2 | G22: 修改二层接口模式和vlan对报文转发的影响
C23: 修改接口工作模式对二层转发的影响测试 | D23: 直接分析 | F23: 1 | G23: 修改接口工作模式对二层报文转发的影响
... C32: 端口最大范围vlan配置测试 | D32: 直接分析 | F32: 1 | G32: 端口添加和删除1-4094个vlan
A33: MAC学习
B34: 动态MAC
C35: MAC地址学习测试 | D35: 流程图 | F35: 4 | G35: 报文源MAC地址学习，广播和组播MAC不学习
C36: MAC转发表老化测试 | D36: 直接分析 | F36: 1 | G36: MAC转发表定时老化
C37: 手动清除MAC转发表测试 | D37: 直接分析 | F37: 1 | G37: MAC表项老化后，对应报文不通
C38: 端口down后自动清除mac转发表测试 | D38: 直接分析 | F38: 1 | G38: 端口down后，端口上的MAC表项清空
C39: MAC转发表达最大后的mac地址学习测试 | D39: 直接分析 | F39: 1 | G39: MAC转发表达到最大容量后的MAC地址学习
C40: 平滑升级后能正常学习MAC地址 | D40: 直接分析 | F40: 1 | G40: 平滑升级后能正常学习MAC地址
B41: 端口迁移
C42: MAC转发表刷新测试 | D42: 直接分析 | F42: 2 | G42: 报文从不同端口进入，MAC转发表刷新，报文转发发生改变
C43: MAC转发表刷新后业务转发测试 | D43: 直接分析 | F43: 1 | G43: MAC转发表刷新，业务转发
C44: MAC表项达最大数量后的端口迁移测试 | D44: 直接分析 | F44: 1 | G44: 最大MAC转发表

Sheet 测试组网设计
A1: 名称 | B1: L2.vlan1
A2: 组网图

Sheet MAC转发
A1: 测试点汇总 | B1: 测试点 | C1: 测试设计方法 | D1: 适用场景 | E1: 用例规模（个） | F1: 测试数据
B2: 根据MAC地址转发表转发业务测试 | C2: 流程图 | E2: 3 | F2: MAC地址转发表指导转发、MAC相同vlan相同转发、MAC相同VLAN不同转发
B3: 广播和未知单播转发测试 | C3: 直接分析 | E3: 1 | F3: 广播、未知单播
B4: L3子接口不进行二层转发测试 | C4: 直接分析 | E4: 1 | F4: L3子接口不能进行二层转发
B5: 聚合口进行二层转发测试 | C5: 直接分析 | E5: 1 | F5: 二层聚合口
B6: 二层转发与策略路由的耦合 | C6: 直接分析 | E6: 1 | F6: 策略路由对二层转发报文不生效
B7: 二层转发与ACL的耦合 | C7: 直接分析 | E7: 1 | F7: 二层转发报文匹配ACL
B8: MAC转发表最大数量下的二层转发测试 | C8: 直接分析 | E8: 1 | F8: MAC转发表达到最大数量后业务转发
A9: 根据MAC地址转发表转发业务测试 | B9: 【设计方法】流程图法
B10: 步骤1:流程图
B12: 步骤2:测试路径分析
B13: 路径编号 | C13: 路径覆盖 | E13: 路径描述
B14: path1 | C14: P1-P3 | E14: 未查找到匹配的MAC表项
B15: path2 | C15: P1-P2-P4 | E15: MAC匹配-VLAN不匹配
B16: path3 | C16: P1-P2-P5 | E16: MAC匹配-VLAN匹配
B17: 【设计方法】直接设计法
B18: 步骤1:逻辑用例设计
B19: 逻辑用例编号 | C19: 测试用例描述 | F19: 覆盖的测试数据 | G19: 测试数据选取结果
B20: L2.vlan.macforward.001 | C20: 未知单播报文转发测试 | F20: 未知单播
B21: L2.vlan.macforward.002 | C21: MAC匹配VLAN不匹配时在VLAN域内泛洪转发 | F21: MAC匹配，VLAN不匹配
B22: L2.vlan.macforward.003 | C22: MAC和VLAN均匹配时按表项转发 | F22: MAC和VLAN都匹配
B23: 步骤2:物理用例设计
B24: 逻辑用例编号 | C24: 用例标题 | D24: 测试数据 | E24: 预置条件 | F24: 测试步骤 | G24: 预期结果
B25: L2.vlan.macforward.001 | C25: 未知单播报文转发测试 | D25: 数据=未知单播 | E25: 1、网元正常启动 2、网元GE0、GE1、GE2分别连接仪表口1、2、3，GE0、GE1、GE2端口模式均为access，vlan配置为vlan1 3、网元上存在mac1+vlan1+GE1的转发表表项 | F25: 1、从仪表1口发送目的mac为mac2，不带vlan的报文，查看仪表2、3口是否收到数据【check1】 2、从仪表1口发送目的mac为mac2，带vlan1的报文，查看端口2、3口是否收到数据【check1】 3、从仪表1口发送目的mac为mac3带vlan2的报文，查看2、3口是否收到数据【check2】 | G25: 【check1】仪表2和3口均收到报文 【check2】仪表2和3口均未收到报文
B26: L2.vlan.macforward.002 | C26: MAC匹配VLAN不匹配时在VLAN域内泛洪测试 | D26: 数据=MAC匹配，VLAN不匹配 | E26: 1、网元正常启动 2、网元GE0、GE1、GE2分别连接仪表口1、2、3，GE0端口模式为trunk，vlan为vlan2和vlan3，GE1、GE2端口模式均为access，GE1端口vlan为vlan2，GE2端口vlan为vlan3 3、网元上存在mac1+vlan1+GE3的转发表表项 | F26: 1、从仪表1口发送目的mac为mac1，带vlan2的报文，查看仪表2、3口是否收到数据【check1】 2、从仪表1口发送目的mac为mac1，带vlan3的报文，查看仪表2、3口是否收到数据【check2】 | G26: 【check1】仪表2口收到报文，3口未收到 【check2】仪表3口收到报文，2口未收到
B27: L2.vlan.macforward.003 | C27: MAC和VLAN均匹配时按表项转发测试 | D27: 数据=MAC和VLAN均匹配 | E27: 1、网元正常启动 2、网元GE0、GE1、GE2分别连接仪表口1、2、3，GE0、GE1、GE2端口模式均为access，vlan配置为vlan1 3、网元上存在mac1+vlan1+GE1的转发表表项 | F27: 1、从仪表1口发送目的mac为mac1，带vlan1的报文，查看仪表2、3口是否收到数据【check1】 2、从仪表1口发送目的mac为mac1，不带vlan的报文，查看仪表2、3口是否收到数据【check1】 3、从仪表2口发送源mac为mac2的报文【check2】 4、从仪表1口发送目的mac为mac2，不带vlan的报文，查看仪表2、3口是否收到数据【check1】 5、从仪表1口发送目的mac为mac2，带vlan1的报文，查看仪表2、3口是否收到数据【check1】 | G27: 【check1】只有仪表2口收到报文 【check2】网元上学习到mac2+vlan1+GE1的表项
B28: L2.vlan.macforward.022 | C28: 报文入端口和出端口相同测试 | D28: 数据=出入端口相同 | E28: 1、网元正常启动 2、网元GE0、GE1、GE2分别连接仪表口1、2、3，GE0、GE1、GE2端口模式均为access，vlan配置为vlan1 | F28: 1、从仪表1口发送不带vlan源mac为mac1的报文，观察网元是否学习到mac表项【check1】 2、从仪表1口发送不带vlan目的mac为mac1的报文，观察仪表2、3口是否收到数据【check2】 3、从仪表2口发送不带vlan目的mac为mac1的报文，观察仪表1、3口是否收到数据【check3】 | G28: 【check1】网元上学习到mac1+vlan1+GE0表项 【check2】仪表2、3口未收到数据 【check3】仪表1口收到数据，3口未收到
A29: 广播和未知单播转发测试 | B29: 【设计方法】直接设计法
B30: 步骤1:逻辑用例设计
B31: 逻辑用例编号 | C31: 测试用例描述 | F31: 覆盖的测试数据 | G31: 测试数据选取结果
B32: L2.vlan.macforward.004 | C32: 广播报文转发测试 | F32: 广播、未知单播
B33: 步骤2:物理用例设计
B34: 逻辑用例编号 | C34: 用例标题 | D34: 测试数据 | E34: 预置条件 | F34: 测试步骤 | G34: 预期结果
B35: L2.vlan.macforward.004 | C35: 广播和组播报文转发测试 | D35: 目的MAC=广播,组播 | E35: 1、网元正常启动 2、网元GE0、GE1、GE2分别连接仪表口1、2、3 | F35: 1、配置网元GE0、GE1和GE2口为access模式，vlan配置为vlan1【check1】 2、从仪表1口发送目的mac为广播（全F），不带vlan的报文，查看仪表2、3口是否收到数据【check2】 3、从仪表1口发送目的mac为广播（全F），带vlan1的报文，查看仪表2、3口是否收到数据【check2】 4、从仪表1口发送目的mac为组播，不带vlan的报文，查看仪表2、3口是否收到数据【check2】 5、从仪表1口发送目的mac为组播，带vlan1的报文，查看仪表2、3口是否收到数据【check2】 | G35: 【check1】配置成功 【check2】仪表2口和3口均收到数据
A36: L3子接口不进行二层转发测试 | B36: 【设计方法】直接设计法
B37: 步骤1:逻辑用例设计
B38: 逻辑用例编号 | C38: 测试用例描述 | F38: 覆盖的测试数据 | G38: 测试数据选取结果
B39: L2.vlan.macforward.005 | C39: 二层转发和L3子接口耦合 | F39: 不涉及
B40: 步骤2:物理用例设计
B41: 逻辑用例编号 | C41: 用例标题 | D41: 测试数据 | E41: 预置条件 | F41: 测试步骤 | G41: 预期结果
...

Sheet VLAN隔离
A1: 测试点汇总 | B1: 测试点 | C1: 测试设计方法 | D1: 适用场景 | E1: 用例规模（个） | F1: 测试数据
B2: 不同模式下VLAN配置测试 | C2: 等价类划分&数据组合 | E2: 4 | F2: access和trunk模式下的vlan配置
B3: access入方向对二层报文的处理测试 | C3: 直接分析 | E3: 3 | F3: access入方向对带vlan和不带vlan报文的处理
B4: access出方向对二层报文的处理测试 | C4: 直接分析 | E4: 3 | F4: access出方向对带vlan和不带vlan报文的处理
B5: trunk入方向对二层报文的处理测试 | C5: 直接分析 | E5: 3 | F5: trunk入方向对带vlan和不带vlan报文的处理
B6: trunk出方向对二层报文的处理测试 | C6: 直接分析 | E6: 3 | F6: trunk出方向对带vlan和不带vlan报文的处理
B7: access端口之间报文转发测试 | C7: 直接分析 | E7: 1 | F7: access端口之间报文转发
B8: trunk端口之间报文转发测试 | C8: 直接分析 | E8: 2 | F8: trunk端口之间报文转发
B9: access和trunk之间报文转发测试 | C9: 直接分析 | E9: 2 | F9: access和trunk之间报文转发
B10: 多层vlan报文转发测试 | C10: 直接分析 | E10: 3 | F10: access和trunk模式下的多层vlan报文转发
B11: 特殊vlan报文转发测试 | C11: 直接分析 | E11: 1 | F11: vlan为0和4095的报文转发
B12: 修改二层接口tag属性对报文转发的影响测试 | C12: 直接分析 | E12: 2 | F12: 修改二层接口模式和vlan对报文转发的影响
B13: 修改接口工作模式对二层转发的影响测试 | C13: 直接分析 | E13: 1 | F13: 修改接口工作模式对二层报文转发的影响
... B22: 端口最大范围vlan配置测试 | C22: 直接分析 | E22: 1 | F22: 端口添加和删除1-4094个vlan
A23: 不同模式下VLAN配置测试 | B23: 【设计方法】等价类划分&数据组合
B24: 步骤1:等价类划分
B25: 等价类划分 | C25: 测试数据 | D25: 有效类 | E25: 无效类
C26: 接口模式 | D26: access | E26: hybrid | F26: 划分方法：无 选取策略：全选 选取结果：测试对象=接口模式：有效值=access，trunk；无效值=hybrid，中文，数字，特殊字符，空
D27: trunk | E27: 超长字符串
E28: 数字
E29: 空
E30: 特殊字符
C31: 单个vlan | D31: 1-4094 | E31: 0 | F31: 划分方法：无 选取策略：全选 选取结果：测试对象=单个vlan;有效值=1-4094;无效值=
E32: 4095
E33: <1
E34: >4094
E35: 英文
E36: 中文
E37: 特殊字符
E38: 空
C40: 多个vlan | D40: 逗号连接单个1-4094范围的数字 | E40: 逗号连接字符串中存在<1的数 | F40: 划分方法：无 选取策略：全选 选取结果：测试对象=多个vlan;有效值=逗号连接单个1-4094范围的数字，"-"连接的1-4094内的范围，空;无效值=逗号连接字符串中存在<1的数，逗号连接字符串中存在>4094的数，"-"连接的起始值大于结束值，英文，中文，特殊字符，超长字符串
D41: "-"连接的1-4094内范围 | E41: 逗号连接字符串中存在>4094的数
D42: 空 | E42: "-"连接的起始值大于结束值
D43: 单个数字和范围组合 | E43: 英文
E44: 中文
E45: 特殊字符
E46: 超长字符串
B47: 步骤2:数据组合
B48: 数据组合 | C48: 测试数据 | D48: 数据取值 | E48: 组合数据分析 | F48: 约束条件和组合策略 | G48: 组合结果
C49: 接口模式 | D49: access | E49: 单个vlan=1-4094 | F49: 约束条件：接口模式为access时只能配置单个vlan 组合策略：全组合 | G49: 接口模式=access;trunk;单个vlan:有效值=1-4094之间任一值;无效值=0,4095,空,<1，>4094，英文，中文，特殊字符
...

Sheet 动态MAC
A1: 测试点汇总 | B1: 测试点 | C1: 测试设计方法 | D1: 适用场景 | E1: 用例规模（个） | F1: 测试数据
B2: MAC地址学习测试 | C2: 流程图 | E2: 4 | F2: 报文源MAC地址学习，广播和组播MAC不学习
B3: MAC转发表老化测试 | C3: 直接分析 | E3: 1 | F3: MAC转发表定时老化
B4: 手动清除MAC转发表测试 | C4: 直接分析 | E4: 1 | F4: MAC表项老化后，对应报文不通
B5: 端口down后自动清除mac转发表测试 | C5: 直接分析 | E5: 1 | F5: 端口down后，端口上的MAC表项清空
B6: MAC转发表达最大后的mac地址学习测试 | C6: 直接分析 | E6: 1 | F6: MAC转发表达到最大容量后的MAC地址学习
B7: 平滑升级后能正常学习MAC地址 | C7: 直接分析 | E7: 1 | F7: 平滑升级后能正常学习MAC地址
A8: MAC地址学习测试 | B8: 【设计方法】流程图法
B9: 步骤1:流程图
H10: P1-P5 P1-P2 | I10: P2-P3 P2-P4 | J10: P3-P6 P3-P7 | K10: P1-P5 P1-P2-P4 P1-P2-P3-P6 P1-P2-P3-P7
B11: 步骤2:测试路径分析
B12: 路径编号 | C12: 路径覆盖 | E12: 路径描述
B13: path1 | C13: P1-P5 | E13: 异常包（源mac是广播或组播、CRC错包）-不学习MAC表项
B14: path2 | C14: P1-P2-P4 | E14: 源MAC不是广播或组播-MAC转发表中不存在相同mac表项-学习MAC+VLAN表项
B15: path3 | C15: P1-P2-P3-P7 | E15: 源MAC不是广播或组播-MAC转发表中存在相同mac表项-MAC转发表中对应表项vlan不同-学习MAC+VLAN表项
B16: path4 | C16: P1-P2-P3-P6 | E16: 源MAC不是广播或组播-MAC转发表中存在相同mac表项-MAC转发表中对应表项vlan相同-表项刷新
B17: 【设计方法】直接设计法
B18: 步骤1:逻辑用例设计
B19: 逻辑用例编号 | C19: 测试用例描述 | F19: 覆盖的测试数据 | G19: 测试数据选取结果
B20: L2.mac.Dynamic.001 | C20: 源MAC为广播和组播时不学习MAC地址 | F20: 组播、广播 | G20: 异常包=源MAC为广播，源MAC为组播，CRC错包
B21: L2.mac.Dynamic.002 | C21: 源MAC在MAC转发表中不存在时学习MAC地址 | F21: 源MAC学习
B22: L2.mac.Dynamic.003 | C22: MAC相同vlan不同时学习MAC地址 | F22: MAC相同，vlan不同
B23: L2.mac.Dynamic.004 | C23: MAC相同vlan相同时不学习MAC地址 | F23: MAC和vlan均相同
B24: 步骤2:物理用例设计
B25: 逻辑用例编号 | C25: 用例标题 | D25: 测试数据 | E25: 预置条件 | F25: 测试步骤 | G25: 预期结果
B26: L2.mac.Dynamic.001 | C26: 源MAC为非单播时不学习MAC地址测试 | D26: 异常包=源MAC为广播,源MAC为组播,CRC错包 | E26: 1、网元正常启动 2、网元GE1、GE2分别连接仪表口1、2，仪表1、2口配置同网段IP | F26: 1、配置GE1和GE2为交换模式，类型为access，vlanid相同【check1】 2、从仪表1口发送$[异常包]的报文，查看网元是否学习到报文源MAC【check2】 | G26: 【check1】配置成功 【check2】网元未学习到表项
B27: L2.mac.Dynamic.002 | C27: 单播MAC地址学习测试 | D27: 数据=单播mac | E27: 1、网元正常启动 2、网元GE1、GE2分别连接仪表口1、2，仪表1、2口配置同网段IP 3、网元上转发表中不存在mac1和mac2表项 | F27: 1、配置GE1为交换模式，类型为access，vlanid为vlan1【check1】 2、从仪表1口发送源MAC为mac1，不带vlan的报文，查看网元是否学习到报文源mac【check2】 3、配置GE2为交换模式，类型为trunk，default vlan id为vlan1，trunk vlanid为vlan2【check1】 4、从仪表2口发送源MAC为mac2，不带vlan的报文，查看网元是否学习到报文源mac【check3】 | G27: 【check1】配置成功 【check2】网元学习到mac1+vlan1+GE1表项 【check3】网元学习到mac2+vlan1+GE2表项
B28: L2.mac.Dynamic.003 | C28: MAC相同VLAN不同时学习表项测试 | D28: 数据=vlan不同 | E28: 1、网元正常启动 2、网元GE1、GE2分别连接仪表口1、2，仪表1、2口配置同网段IP 3、网元上转发表中不存在mac1表项 | F28: 1、配置GE1为交换模式，类型为trunk，default vlanid为vlan1，trunk vlanid为vlan2【check1】 2、从仪表1口发送源MAC为mac1，不带vlan的报文，查看网元是否学习到报文源mac【check2】 3、从仪表1口发送源MAC为mac1，带vlan2的报文，查看网元是否学习到新表项【check3】 | G28: 【check1】配置成功 【check2】网元学习到mac1+vlan1+GE1表项 【check3】网元学习到mac1+vlan2+GE1表项，步骤2中学习到的表项仍存在
B29: L2.mac.Dynamic.004 | C29: MAC相同VLAN相同时不再学习表项测试 | D29: 数据=mac、vlan相同 | E29: 1、网元正常启动 2、网元GE1、GE2分别连接仪表口1、2，仪表1、2口配置同网段IP 3、网元上转发表中不存在mac1表项 | F29: 1、配置GE1为交换模式，类型为access，vlanid为vlan1【check1】 2、从仪表1口发送源MAC为mac1，不带vlan的报文，查看网元是否学习到报文源mac【check2】 3、从仪表1口发送源MAC为mac1，带vlan1的报文，查看网元是否学习到新表项【check3】 | G29: 【check1】配置成功 【check2】网元学习到mac1+vlan1+GE1表项 【check3】网元未学习到新表项，mac1+vlan1+GE1的表项触发时间更新
A30: MAC转发表老化测试 | B30: 【设计方法】直接设计法
B31: 步骤1:逻辑用例设计
B32: 逻辑用例编号 | C32: 测试用例描述 | F32: 覆盖的测试数据 | G32: 测试数据选取结果
B33: L2.mac.Dynamic.005 | C33: MAC转发表老化测试 | F33: 不涉及
B34: 步骤2:物理用例设计
B35: 逻辑用例编号 | C35: 用例标题 | D35: 测试数据 | E35: 预置条件 | F35: 测试步骤 | G35: 预期结果
B36: L2.mac.Dynamic.005 | C36: MAC转发表老化测试 | D36: 数据=mac老化 | E36: 1、网元正常启动 2、网元GE1、GE2、GE3分别连接仪表口1、2、3，仪表1、2、3口配置同网段IP 3、网元上转发表中不存在mac1表项 | F36: 1、配置GE1为交换模式，类型为access，vlanid为vlan1【check1】 2、从仪表1口发送源MAC为mac1，不带vlan的报文，查看网元是否学习到报文源mac【check2】 3、从仪表2口发送目的MAC为mac1的报文，观察仪表接收情况【check3】 4、等待aging time（5分钟）后，在网元上查看转发表【check4】 5、重复步骤3，观察仪表接收报文情况【check5】 | G36: 【check1】配置成功 【check2】网元学习到mac1+vlan1+GE1表项 【check3】仪表1口收到报文，仪表3口未收到报文 【check4】网元上不存在mac1+vlan1+GE1表项 【check5】仪表1口和3口均收到报文
A37: 手动清除MAC转发表测试 | B37: 【设计方法】直接设计法
B38: 步骤1:逻辑用例设计
B39: 逻辑用例编号 | C39: 测试用例描述 | F39: 覆盖的测试数据 | G39: 测试数据选取结果
B40: L2.mac.Dynamic.006 | C40: 手动清除MAC转发表测试 | F40: 不涉及
...

Sheet 端口迁移
A1: 测试点汇总 | B1: 测试点 | C1: 测试设计方法 | D1: 适用场景 | E1: 用例规模（个） | F1: 测试数据
B2: MAC转发表刷新测试 | C2: 直接分析 | E2: 2 | F2: 报文从不同端口进入，MAC转发表刷新，报文转发发生改变
B3: MAC转发表刷新后业务转发测试 | C3: 直接分析 | E3: 1 | F3: MAC转发表刷新，业务转发
B4: MAC表项达最大数量后的端口迁移测试 | C4: 直接分析 | E4: 1 | F4: 最大MAC转发表
A5: MAC转发表刷新测试 | B5: 【设计方法】直接设计法
B6: 步骤1:逻辑用例设计
B7: 逻辑用例编号 | C7: 测试用例描述 | F7: 覆盖的测试数据 | G7: 测试数据选取结果
B8: L2.mac.migration.001 | C8: 相同MAC和VLAN报文从不同端口进入刷新MAC表项 | F8: 相同报文
B9: L2.mac.migration.002 | C9: 相同MAC不同VLAN报文从不同端口进入 | F9: 相同MAC不同VLAN
B10: 步骤2:物理用例设计
B11: 逻辑用例编号 | C11: 用例标题 | D11: 测试数据 | E11: 预置条件 | F11: 测试步骤 | G11: 预期结果
B12: L2.mac.migration.001 | C12: MAC表项刷新测试 | D12: 数据=相同报文，不同端口 | E12: 1、网元正常启动 2、网元GE1、GE2分别连接仪表口1、2，仪表1、2口配置同网段IP 3、网元上转发表中不存在mac1表项 | F12: 1、配置GE1、GE2为交换模式，类型为access，vlanid为vlan1【check1】 2、从仪表1口发送源mac为mac1，不带vlan的报文，在网元上查看MAC转发表【check2】 3、从仪表2口发送源mac为mac1，不带vlan的报文，在网元上查看MAC转发表【check3】 4、从仪表2口发送源mac为mac1，带vlan1的报文，在网元上查看MAC转发表【check4】 | G12: 【check1】配置成功 【check2】网元学习到mac1+vlan1+GE1表项 【check3】网元学习到mac1+vlan1+GE2表项，mac1+vlan1+GE1表项不存在 【check4】网元MAC转发表表项未刷新
B13: L2.mac.migration.002 | C13: MAC相同VLAN不同时从不同端口进入学习MAC表项测试 | D13: 数据=mac相同vlan不同，不同端口 | E13: 1、网元正常启动 2、网元GE1、GE2分别连接仪表口1、2，仪表1、2口配置同网段IP 3、网元上转发表中不存在mac1表项 | F13: 1、配置GE1为交换模式，类型为access，vlanid为vlan1；GE2为交换模式，类型为access，vlanid为vlan2【check1】 2、从仪表1口发送源mac为mac1，不带vlan的报文，在网元上查看MAC转发表【check2】 3、从仪表2口发送源mac为mac1，不带vlan的报文，在网元上查看MAC转发表【check3】 | G13: 【check1】配置成功 【check2】网元学习到mac1+vlan1+GE1表项 【check3】网元学习到mac1+vlan2+GE2表项，mac1+vlan1+GE1表项仍存在
A14: MAC转发表刷新后业务转发测试 | B14: 【设计方法】直接设计法
B15: 步骤1:逻辑用例设计
B16: 逻辑用例编号 | C16: 测试用例描述 | F16: 覆盖的测试数据 | G16: 测试数据选取结果
B17: L2.mac.migration.003 | C17: MAC转发表刷新后业务转发测试 | F17: 不涉及
B18: 步骤2:物理用例设计
B19: 逻辑用例编号 | C19: 用例标题 | D19: 测试数据 | E19: 预置条件 | F19: 测试步骤 | G19: 预期结果
B20: L2.mac.migration.003 | C20: MAC转发表刷新后业务转发测试 | D20: 数据=MAC表项刷新 | E20: 1、网元正常启动 2、网元GE1、GE2和GE3分别连接仪表口1、2、3，仪表1、2、3口配置同网段IP 3、网元上转发表中不存在mac1表项 | F20: 1、配置GE1、GE2和GE3为交换模式，类型为access，vlanid为vlan1【check1】 2、从仪表1口发送源mac为mac1，不带vlan的报文，在网元上查看MAC转发表【check2】 3、从仪表3口发送目的mac为mac1，不带vlan的报文，查看仪表1口和2口是否收到报文【check3】 4、从仪表2口发送源mac为mac1，不带vlan的报文，在网元上查看MAC转发表【check4】 5、重复步骤3【check5】 | G20: 【check1】配置成功 【check2】网元学习到mac1+vlan1+GE1表项 【check3】仪表1口收到报文，仪表2口未收到报文 【check4】网元学习到mac1+vlan1+GE2表项，mac1+vlan1+GE1表项不存在 【check5】仪表1口未收到报文，仪表2口收到报文
A21: MAC表项达最大数量后的端口迁移测试 | B21: 【设计方法】直接设计法
B22: 步骤1:逻辑用例设计
B23: 逻辑用例编号 | C23: 测试用例描述 | F23: 覆盖的测试数据 | G23: 测试数据选取结果
B24: L2.mac.migration.004 | C24: MAC表项达最大数量后的端口迁移测试 | F24: 不涉及
B25: 步骤2:物理用例设计
B26: 逻辑用例编号 | C26: 用例标题 | D26: 测试数据 | E26: 预置条件 | F26: 测试步骤 | G26: 预期结果
B27: L2.mac.migration.004 | C27: MAC表项达最大数量后的端口迁移测试 | D27: 数据=最大表项 | E27: 1、网元正常启动 2、网元GE1、GE2分别连接仪表口1、2，仪表1、2口配置同网段IP 3、网元上转发表中不存在mac1表项 | F27: 1、配置GE1、GE2和GE3为交换模式，类型为access，vlanid相同【check1】 2、从仪表1口发送源mac变化mac.max个的报文（包含mac1），查看网元是否学习到报文源MAC【check2】 3、从仪表2口发送源mac为mac1的报文，查看网元mac表项【check3】 | G27: 【check1】配置成功 【check2】网元学习到mac.max个表项，其中包括mac1+vlan1+GE1表项 【check3】网元表项数量未变化，mac1+vlan1+GE1表项不存在，刷新为mac1+vlan1+GE2，其他表项未发生变化

Sheet 用例全集
A1: 一级目录 | B1: 二级目录 | C1: 三级目录 | D1: 四级目录 | E1: 五级目录 | F1: 用例名称* | G1: 编号* | H1: ID* | I1: 用例级别* | J1: 组网描述* | K1: 组网约束 | L1: 预置条件 | M1: 测试步骤* | N1: 预期结果* | O1: 适用版本* | P1: 设备类型* | Q1: 单板类型 | R1: 关键词 | S1: 测试类型* | T1: 是否自动化* | U1: 需求编号 | V1: 备注 | AH1: LEVEL0 | AI1: LEVEL1 | AJ1: LEVEL2 | AK1: LEVEL3 | AL1: LEVEL4 | AM1: LEVEL5 | AN1: LEVEL6 | AP1: 配置测试 | AQ1: 功能测试 | AR1: 耦合测试 | AS1: 可靠性测试 | AT1: 性能测试 | AU1: 升级测试
A2: 网络特性
B3: 二层交换
C4: 二层转发
D5: 配置管理
E6: 二层配置
F7: 接口模式为无效值修改端口vlan测试 | G7: L2.vlan.isolation.001 | H7: 1100101 | I7: LEVEL0 | L7: 1、网元正常启动 2、GE1端口工作模式为交换 | M7: 1、修改GE1模式为hybrid，配置VLAN ID为1-4094之间任一值【check1】 2、修改GE1模式为中文，配置VLAN ID为1-4094之间任一值【check1】 3、修改GE1模式为数字，配置VLAN ID为1-4094之间任一值【check1】 4、修改GE1模式为特殊字符，配置VLAN ID为1-4094之间任一值【check1】 5、修改GE1模式为空，配置VLAN ID为1-4094之间任一值【check1】 | N7: 【check1】配置失败 | O7: NGFW_V60R1C00 | P7: J1900,C236,EP | T7: 是
F8: 接口模式为access时修改端口vlan测试 | G8: L2.vlan.isolation.002 | H8: 1100102 | I8: LEVEL0 | L8: 1、网元正常启动 2、GE1端口工作模式为交换 | M8: 1、修改GE1模式为access，配置 VLAN ID为1-4094之间任一值【check1】 2、修改VLAN ID为0【check2】 3、修改VLAN ID为4095【check2】 4、修改VLAN ID为空【check2】 5、修改VLAN ID为<1，>4094，英文，中文，特殊字符【check2】 | N8: 【check1】配置成功，日志中存在对应记录 【check2】配置失败 | O8: NGFW_V60R1C00 | P8: J1900,C236,EP | T8: 是
F9: 接口模式为trunk修改端口Default VLAN ID测试 | G9: L2.vlan.isolation.003 | H9: 1100103 | I9: LEVEL0 | L9: 1、网元正常启动 2、GE1端口工作模式为交换 | M9: 1、修改GE1模式为trunk，配置 VLAN ID为1-4094之间任一值【check1】 2、修改Default VLAN ID为0【check2】 3、修改Default VLAN ID为4095【check2】 4、修改Default VLAN ID为空【check2】 5、修改Default VLAN ID为<1，>4094，英文，中文，特殊字符【check2】 | N9: 【check1】配置成功，日志中存在对应记录 【check2】配置失败 | O9: NGFW_V60R1C00 | P9: J1900,C236,EP | T9: 是
F10: 接口模式为trunk修改端口Trunk VLAN ID测试 | G10: L2.vlan.isolation.004 | H10: 1100104 | I10: LEVEL0 | L10: 1、网元正常启动 2、GE1端口工作模式为交换 | M10: 1、修改GE1模式为trunk，配置Trunk VLAN ID为逗号连接单个1-4094范围的数字【check1】 2、修改GE1模式为trunk，配置Trunk VLAN ID为"-"连接的1-4094内的范围【check1】 3、修改GE1模式为trunk，配置Trunk VLAN ID为空【check1】 4、修改Trunk VLAN ID为逗号连接字符串中存在<1的数，逗号连接字符串中存在>4094的数，"-"连接的起始值大于结束值，英文，中文，特殊字符，超长字符串【check2】 | N10: 【check1】配置成功，日志中存在对应记录 【check2】配置失败 | O10: NGFW_V60R1C00 | P10: J1900,C236,EP | T10: 是
F11: 端口最大范围vlan配置测试 | G11: L2.vlan.isolation.040 | H11: 1100140 | I11: LEVEL1 | L11: 1、网元正常启动 | M11: 1、配置GE1为交换模式，类型为trunk，default vlanid为vlan1，trunk vlanid为1-4094【check1】 2、配置GE2为交换模式，类型为trunk，default vlanid为vlan1，trunk vlanid为1-4094【check2】 3、在三层接口上配置1-4094个子接口【check3】 4、修改GE1，删除trunk vlanid中的值【check3】 | N11: 【check1】配置成功，下发成功时间不超过5s 【check2】配置成功，下发成功时间不超过3s 【check3】配置成功 【check4】删除成功，下发成功时间不超过3s | O11: NGFW_V60R1C00 | P11: J1900,C236,EP | T11: 是
D12: vlan转发
E13: MAC转发
F14: 未知单播报文转发测试 | G14: L2.vlan.macforward.001 | H14: 1101101 | I14: LEVEL2 | L14: 1、网元正常启动 2、网元GE0、GE1、GE2分别连接仪表口1、2、3，GE0、GE1、GE2端口模式均为access，vlan配置为vlan1 3、网元上存在mac1+vlan1+GE1的转发表表项 | M14: 1、从仪表1口发送目的mac为mac2，不带vlan的报文，查看仪表2、3口是否收到数据【check1】 2、从仪表1口发送目的mac为mac2，带vlan1的报文，查看端口2、3口是否收到数据【check1】 3、从仪表1口发送目的mac为mac3带vlan2的报文，查看2、3口是否收到数据【check2】 | N14: 【check1】仪表2和3口均收到报文 【check2】仪表2和3口均未收到报文 | O14: NGFW_V60R1C00 | P14: J1900,C236,EP | T14: 是
F15: MAC匹配VLAN不匹配时在VLAN域内泛洪测试 | G15: L2.vlan.macforward.002 | H15: 1101102 | I15: LEVEL2 | L15: 1、网元正常启动 2、网元GE0、GE1、GE2分别连接仪表口1、2、3，GE0端口模式为trunk，vlan为vlan2和vlan3，GE1、GE2端口模式均为access，GE1端口vlan为vlan2，GE2端口vlan为vlan3 3、网元上存在mac1+vlan1+GE3的转发表表项 | M15: 1、从仪表1口发送目的mac为mac1，带vlan2的报文，查看仪表2、3口是否收到数据【check1】 2、从仪表1口发送目的mac为mac1，带vlan3的报文，查看仪表2、3口是否收到数据【check2】 | N15: 【check1】仪表2口收到报文，3口未收到 【check2】仪表3口收到报文，2口未收到 | O15: NGFW_V60R1C00 | P15: J1900,C236,EP | T15: 是
F16: MAC和VLAN均匹配时按表项转发测试 | G16: L2.vlan.macforward.003 | H16: 1101103 | I16: LEVEL2 | L16: 1、网元正常启动 2、网元GE0、GE1、GE2分别连接仪表口1、2、3，GE0、GE1、GE2端口模式均为access，vlan配置为vlan1 3、网元上存在mac1+vlan1+GE1的转发表表项 | M16: 1、从仪表1口发送目的mac为mac1，带vlan1的报文，查看仪表2、3口是否收到数据【check1】 2、从仪表1口发送目的mac为mac1，不带vlan的报文，查看仪表2、3口是否收到数据【check1】 3、从仪表2口发送源mac为mac2的报文【check2】 4、从仪表1口发送目的mac为mac2，不带vlan的报文，查看仪表2、3口是否收到数据【check1】 5、从仪表1口发送目的mac为mac2，带vlan1的报文，查看仪表2、3口是否收到数据【check1】 | N16: 【check1】只有仪表2口收到报文 【check2】网元上学习到mac2+vlan1+GE1的表项 | O16: NGFW_V60R1C00 | P16: J1900,C236,EP | T16: 是
F17: 报文入端口和出端口相同测试 | G17: L2.vlan.macforward.004 | H17: 1101104 | I17: LEVEL2 | L17: 1、网元正常启动 2、网元GE0、GE1、GE2分别连接仪表口1、2、3，GE0、GE1、GE2端口模式均为access，vlan配置为vlan1 | M17: 1、从仪表1口发送不带vlan源mac为mac1的报文，观察网元是否学习到mac表项【check1】 2、从仪表1口发送不带vlan目的mac为mac1的报文，观察仪表2、3口是否收到数据【check2】 3、从仪表2口发送不带vlan目的mac为mac1的报文，观察仪表1、3口是否收到数据【check3】 | N17: 【check1】网元上学习到mac1+vlan1+GE0表项 【check2】仪表2、3口未收到数据 【check3】仪表1口收到数据，3口未收到 | O17: NGFW_V60R1C00 | P17: J1900,C236,EP | T17: 是
F18: 广播和组播报文转发测试 | G18: L2.vlan.macforward.005 | H18: 1101105 | I18: LEVEL2 | L18: 1、网元正常启动 2、网元GE0、GE1、GE2分别连接仪表口1、2、3 | M18: 1、配置网元GE0、GE1和GE2口为access模式，vlan配置为vlan1【check1】 2、从仪表1口发送目的mac为广播（全F），不带vlan的报文，查看仪表2、3口是否收到数据【check2】 3、从仪表1口发送目的mac为广播（全F），带vlan1的报文，查看仪表2、3口是否收到数据【check2】 4、从仪表1口发送目的mac为组播，不带vlan的报文，查看仪表2、3口是否收到数据【check2】 5、从仪表1口发送目的mac为组播，带vlan1的报文，查看仪表2、3口是否收到数据【check2】 | N18: 【check1】配置成功 【check2】仪表2口和3口均收到数据 | O18: NGFW_V60R1C00 | P18: J1900,C236,EP | T18: 是
F19: 二层转发和三层子接口的耦合测试 | G19: L2.vlan.macforward.006 | H19: 1101106 | I19: LEVEL5 | L19: 1、网元正常启动 2、GE0为路由模式，GE0上存在子接口GE0.vlan1，子接口上存在IP地址 3、GE0、GE1、GE2分别连接仪表口123 | M19: 1、配置网元GE1、GE2口为access，vlan配置为vlan1【check1】 2、从仪表2口发送带vlan1的报文，观察仪表1和3口是否收到报文【check2】 | N19: 【check1】配置成功 【check2】仪表1口未收到报文，仪表3口收到报文 | O19: NGFW_V60R1C00 | P19: J1900,C236,EP | T19: 是
F20: 二层聚合口业务转发测试 | G20: L2.vlan.macforward.007 | H20: 1101107 | I20: LEVEL5 | L20: 1、网元正常启动 2、网元上存在二层聚合口bond1 3、bond1、GE1和GE2分别连接仪表口123 | M20: 1、配置bond1、GE1、GE2端口模式为access，vlan为vlan1【check1】 2、从仪表2口发送不带vlan的报文，查看仪表1和3口是否收到数据【check2】 3、从仪表2口发送带vlan1的报文，查看仪表1和3口是否收到数据【check2】 4、从仪表1口发送不带vlan的报文，查看仪表2和3口是否收到数据【check3】 5、从仪表1口发送带vlan1的报文，查看仪表2和3口是否收到数据【check3】 | N20: 【check1】配置成功 【check2】仪表1和3口收到报文 【check3】仪表2和3口收到报文 | O20: NGFW_V60R1C00 | P20: J1900,C236,EP | T20: 是
F21: 二层业务不匹配策略路由测试 | G21: L2.vlan.macforward.008 | H21: 1101108 | I21: LEVEL5 | L21: 1、网元正常启动 2、网元GE0、GE1、GE2分别连接仪表口123 | M21: 1、配置GE0和GE1端口模式为access，vlan为vlan1【check1】 2、从仪表1口发送不带vlan和带vlan1的报文，查看仪表2口是否收到【check2】 3、在网元上添加一条策略路由，入接口为GE0，下一跳网关为仪表3口IP【check3】 4、查看仪表2口和3口是否收到数据【check4】 | N21: 【check1】配置成功 【check2】仪表2口收到仪表1口发送的两种报文 【check3】添加成功 【check4】仪表2口收到报文，仪表3口未收到 | O21: NGFW_V60R1C00 | P21: J1900,C236,EP | T21: 是
F22: 二层转发与ACL的耦合测试 | G22: L2.vlan.macforward.009 | H22: 1101109 | I22: LEVEL5 | L22: 1、网元正常启动 2、网元GE0、GE1分别连接仪表口1、2 3、网元默认策略动作为阻断 | M22: 1、配置GE0和GE1端口模式为access，vlan为vlan1【check1】 2、从仪表1口发送目的mac为mac1，不带vlan的报文，在仪表2口查看是否收到数据【check2】 3、修改默认策略动作为允许 4、查看仪表2口是否收到数据【check3】 5、新建一条控制策略，目的mac为mac1，动作为阻断【check4】 6、重复步骤4【check2】 7、修改自定义控制策略动作为允许，重复步骤4【check3】 | N22: 【check1】配置成功 【check2】仪表2口未收到1口发出的报文 【check3】仪表2口收到1口发出的报文 【check4】添加成功 | O22: NGFW_V60R1C00 | P22: J1900,C236,EP | T22: 是
F23: MAC转发表达到最大数量后的二层转发测试 | G23: L2.vlan.macforward.010 | H23: 1101110 | I23: LEVEL4 | L23: 1、网元正常启动 2、网元GE1、GE2、GE3分别连接仪表口1、2、3，仪表1、2、3口配置同网段IP 3、网元上MAC转发表中数量为mac.max，表项中不存在mac1 | M23: 1、配置GE1、GE2、GE3为交换模式，类型为access，vlanid为vlan1【check1】 2、从仪表1口发送源mac为mac1不带vlan的报文，观察业务情况【check2】 3、从仪表2口发送目的mac为mac1不带vlan的报文，观察业务情况【check3】 | N23: 【check1】配置成功 【check2】仪表2、3口均收到报文 【check3】仪表1、3口均收到报文 | O23: NGFW_V60R1C00 | P23: J1900,C236,EP | T23: 是
E24: VLAN隔离
F25: access入方向对不带vlan报文的处理测试 | G25: L2.vlan.isolation.005 | H25: 1101201 | I25: LEVEL2 | L25: 1、网元正常启动 2、GE2接口为trunk，defaultvlan为vlan2，vlanid为vlan1 3、GE1和GE2分别连接仪表口1、2，仪表1、2口配置同网段IP | M25: 1、配置GE1为二层access，vlan id为vlan1【check1】 2、从仪表1口发送不带vlan的报文，查看GE1口是否收到报文【check2】 3、在仪表2口抓包查看报文内容【check3】 | N25: 【check1】配置成功 【check2】GE1口收到报文 【check3】报文中存在一层vlan，值为vlan1 | O25: NGFW_V60R1C00 | P25: J1900,C236,EP | T25: 是
F26: access入方向对带一层vlan报文的处理测试 | G26: L2.vlan.isolation.006 | H26: 1101201 | I26: LEVEL2 | L26: 1、网元正常启动 2、GE2接口为trunk，defaultvlan为vlan2，vlanid为vlan1 3、GE1和GE2分别连接仪表口1、2，仪表1、2口配置同网段IP | M26: 1、配置GE1为二层access，vlan id为vlan1【check1】 2、从仪表1口发送带vlan1的报文，查看GE1口是否收到报文【check2】 3、在仪表2口抓包查看报文内容【check3】 4、从仪表1口发送带vlan2的报文，查看GE1口是否收到报文【check4】 | N26: 【check1】配置成功 【check2】GE1口收到报文 【check3】报文中存在一层vlan，值为vlan1 【check4】GE1口未收到报文 | O26: NGFW_V60R1C00 | P26: J1900,C236,EP | T26: 是
F27: access入方向对带两层vlan报文的处理测试 | G27: L2.vlan.isolation.007 | H27: 1101201 | I27: LEVEL3 | L27: 1、网元正常启动 2、GE2接口为trunk，defaultvlan为vlan2，vlanid为vlan1 3、GE1和GE2分别连接仪表口1、2，仪表1、2口配置同网段IP | M27: 1、配置GE1为二层access，vlan id为vlan1【check1】 2、从仪表1口发送带两层vlan的报文（外层vlan为vlan1，内层vlan为vlan2），查看GE1口是否收到报文【check2】 3、在仪表2口抓包查看报文内容【check3】 4、从仪表1口发送带外层为vlan2，内层为vlan1的报文，查看GE1口是否收到报文【check4】 | N27: 【check1】配置成功 【check2】GE1口收到报文 【check3】报文中存在两层vlan，外层为vlan1，内层为vlan2 【check4】GE1口未收到报文 | O27: NGFW_V60R1C00 | P27: J1900,C236,EP | T27: 是
F28: access出方向对不带vlan报文的处理测试 | G28: L2.vlan.isolation.008 | H28: 1101201 | I28: LEVEL2 | L28: 1、网元正常启动 2、GE1、GE2为access，vlan为vlan1 3、GE1和GE3分别连接仪表口1、2，GE3和仪表2口互通 | M28: 1、将GE1和GE2加入bvi接口中，vlanid为vlan1，配置IP与仪表1口互通【check1】 2、从仪表2口发送不带vlan的报文，查看仪表1口是否收到报文【check2】 3、在仪表1口抓包查看报文内容【check3】 | N28: 【check1】配置成功 【check2】仪表1口收到报文 【check3】报文中不存在vlan | O28: NGFW_V60R1C00 | P28: J1900,C236,EP | T28: 是
F29: access出方向对带一层vlan报文的处理测试 | G29: L2.vlan.isolation.009 | H29: 1101201 | I29: LEVEL2 | L29: 1、网元正常启动 2、GE2接口为trunk，defaultvlan为vlan2，vlanid为vlan1 3、GE1和GE2分别连接仪表口1、2，仪表1、2口配置同网段IP | M29: 1、配置GE1为二层access，vlan id为vlan1【check1】 2、从仪表2口发送带vlan1的报文，查看仪表1口是否收到报文【check2】 3、在仪表1口抓包查看报文内容【check3】 4、从仪表2口发送带vlan2的报文，查看GE1口是否收到报文【check4】 | N29: 【check1】配置成功 【check2】仪表1口收到报文 【check3】报文中不存在vlan 【check4】GE1口未收到报文 | O29: NGFW_V60R1C00 | P29: J1900,C236,EP | T29: 是
F30: access出方向对带两层vlan报文的处理测试 | G30: L2.vlan.isolation.010 | H30: 1101201 | I30: LEVEL3 | L30: 1、网元正常启动 2、GE2接口为trunk，defaultvlan为vlan2，vlanid为vlan1 3、GE1和GE2分别连接仪表口1、2，仪表1、2口配置同网段IP | M30: 1、配置GE1为二层access，vlan id为vlan1【check1】 2、从仪表2口发送带两层vlan的报文（外层vlan为vlan1，内层vlan为vlan2），查看仪表1口是否收到报文【check2】 3、在仪表1口抓包查看报文内容【check3】 4、从仪表2口发送带外层为vlan2，内层为vlan1的报文，查看GE1口是否收到报文【check4】 | N30: 【check1】配置成功 【check2】仪表1口收到报文 【check3】报文中存在一层vlan，值为vlan2 【check4】仪表1口未收到报文 | O30: NGFW_V60R1C00 | P30: J1900,C236,EP | T30: 是
F31: trunk入方向对不带vlan报文的处理测试 | G31: L2.vlan.isolation.011 | H31: 1101201 | I31: LEVEL2 | L31: 1、网元正常启动 2、GE2接口为trunk，defaultvlan为vlan2，vlanid为vlan1、vlan3、vlan4 3、GE1和GE2分别连接仪表口1、2，仪表1、2口配置同网段IP | M31: 1、配置GE1为二层trunk，default vlan id为vlan1【check1】 2、从仪表1口发送不带vlan的报文，查看GE1口是否收到报文【check2】 3、查看仪表2口是否收到报文并抓包【check3】 | N31: 【check1】配置成功 【check2】GE1口收到报文 【check3】报文中存在一层vlan，值为vlan1，报文tpid为8100 | O31: NGFW_V60R1C00 | P31: J1900,C236,EP | T31: 是
F32: trunk入方向对带一层vlan报文的处理测试 | G32: L2.vlan.isolation.012 | H32: 1101201 | I32: LEVEL2 | L32: 1、网元正常启动 2、GE2接口为trunk，defaultvlan为vlan2，vlanid为vlan1、vlan3、vlan4 3、GE1和GE2分别连接仪表口1、2，仪表1、2口配置同网段IP | M32: 1、配置GE1为二层trunk，default vlan id为vlan1，trunk vlan id为vlan3、vlan4【check1】 2、从仪表1口发送带vlan1的报文，查看GE1口是否收到报文【check2】 3、查看仪表2口是否收到报文并抓包【check3】 4、从仪表1口发送带vlan3的报文，查看仪表2口是否收到报文并抓包【check4】 5、从仪表1口发送带vlan4的报文，查看仪表2口是否收到报文并抓包【check5】 6、从仪表1口发送带vlan2的报文，查看仪表2口是否收到【check6】 | N32: 【check1】配置成功 【check2】GE1口收到报文 【check3】仪表2口收到报文，报文中存在一层vlan，值为vlan1 【check4】仪表2口收到报文，报文中存在一层vlan，值为vlan3 【check5】仪表2口收到报文，报文中存在一层vlan，值为vlan4 【check6】仪表2口未收到报文 | O32: NGFW_V60R1C00 | P32: J1900,C236,EP | T32: 是
F33: trunk入方向对带两层vlan报文的处理测试 | G33: L2.vlan.isolation.013 | H33: 1101201 | I33: LEVEL3 | L33: 1、网元正常启动 2、GE2接口为trunk，defaultvlan为vlan2，vlanid为vlan1、vlan3、vlan4 3、GE1和GE2分别连接仪表口1、2，仪表1、2口配置同网段IP | M33: 1、配置GE1为二层trunk，default vlan id为vlan1，trunk vlanid为vlan3、vlan4【check1】 2、从仪表1口发送带两层vlan的报文（外层vlan为vlan1，内层vlan为vlan2），查看GE1口是否收到报文【check2】 3、查看仪表2口是否收到报文并抓包【check3】 4、从仪表1口发送带外层为vlan3，内层为vlan2的报文，查看仪表2口是否收到报文并抓包【check4】 5、从仪表1口发送带外层为vlan4，内层为vlan2的报文，查看仪表2口是否收到报文并抓包【check5】 6、从仪表1口发送带外层vlan2，内层vlan1的报文，查看仪表2口是否收到报文【check6】 | N33: 【check1】配置成功 【check2】GE1口收到报文 【check3】报文中存在两层vlan，外层为vlan1，内层为vlan2 【check4】报文中存在两层vlan，外层为vlan3，内层为vlan2 【check5】报文中存在两层vlan，外层为vlan4，内层为vlan2 【check6】仪表2口未收到报文 | O33: NGFW_V60R1C00 | P33: J1900,C236,EP | T33: 是
F34: trunk出方向对不带vlan报文的处理测试 | G34: L2.vlan.isolation.014 | H34: 1101201 | I34: LEVEL2 | L34: 1、网元正常启动 2、GE1、GE2为trunk，vlan为vlan1 3、GE1和GE3分别连接仪表口1、2，GE3和仪表2口互通 | M34: 1、将GE1和GE2加入bvi接口中，vlanid为vlan1，配置IP与仪表1口互通【check1】 2、从仪表2口发送不带vlan的报文，查看仪表1口是否收到报文【check2】 3、在仪表1口抓包查看报文内容【check3】 | N34: 【check1】配置成功 【check2】仪表1口收到报文 【check3】报文中不存在vlan | O34: NGFW_V60R1C00 | P34: J1900,C236,EP | T34: 是
F35: trunk出方向对带一层vlan报文的处理测试 | G35: L2.vlan.isolation.015 | H35: 1101201 | I35: LEVEL2 | L35: 1、网元正常启动 2、GE2接口为trunk，defaultvlan为vlan2，vlanid为vlan1、vlan3、vlan4 3、GE1和GE2分别连接仪表口1、2，仪表1、2口配置同网段IP | M35: 1、配置GE1为二层trunk，default vlan id为vlan1，trunk vlan id为vlan3、vlan4【check1】 2、从仪表2口发送带vlan1的报文，查看仪表1口是否收到报文并抓包【check2】 3、从仪表2口发送带vlan3的报文，查看仪表1口是否收到报文并抓包【check3】 4、从仪表2口发送带vlan4的报文，查看仪表1口是否收到报文并抓包【check4】 5、从仪表2口发送带vlan2的报文，查看仪表1口是否收到【check5】 | N35: 【check1】配置成功 【check2】仪表1口收到报文，报文中不存在vlan 【check3】仪表1口收到报文，报文中存在一层vlan为vlan3 【check4】仪表1口收到报文，报文中存在一层vlan为vlan4 【check5】仪表1口未收到报文 | O35: NGFW_V60R1C00 | P35: J1900,C236,EP | T35: 是
F36: trunk出方向对带两层vlan报文的处理测试 | G36: L2.vlan.isolation.016 | H36: 1101201 | I36: LEVEL3 | L36: 1、网元正常启动 2、GE2接口为trunk，defaultvlan为vlan2，vlanid为vlan1、vlan3、vlan4 3、GE1和GE2分别连接仪表口1、2，仪表1、2口配置同网段IP | M36: 1、配置GE1为二层trunk，default vlan id为vlan1，trunk vlan id为vlan3、vlan4【check1】 2、从仪表2口发送带外层vlan1，内层vlan2的报文，查看仪表1口是否收到报文并抓包【check2】 3、从仪表2口发送带外层vlan3，内层vlan2的报文，查看仪表1口是否收到报文并抓包【check3】 4、从仪表2口发送带外层vlan4，内层vlan2的报文，查看仪表1口是否收到报文并抓包【check4】 5、从仪表2口发送带外层vlan2，内层vlan1的报文，查看仪表1口是否收到【check5】 | N36: 【check1】配置成功 【check2】仪表1口收到报文，报文中存在一层vlan为vlan2 【check3】仪表1口收到报文，报文中存在两层vlan外层为vlan3，内层为vlan2 【check4】仪表1口收到报文，报文中存在两层vlan外层为vlan4，内层为vlan2 【check5】仪表1口未收到报文 | O36: NGFW_V60R1C00 | P36: J1900,C236,EP | T36: 是
... F59: 拔插网线对二层转发的影响测试 | G59: L2.vlan.isolation.039 | H59: 1101201 | I59: LEVEL4 | L59: 1、网元正常启动 2、网元GE1、GE2分别连接仪表口1、2，仪表1、2口配置同网段IP | M59: 1、配置GE1、GE2为交换模式，类型为access，vlan id为vlan1【check1】 2、从仪表两端发送不带vlan、带一层vlan1、带外层vlan1内层vlan2的报文，观察业务【check2】 3、拔插GE1口网线，观察业务【check3】 4、修改端口类型为trunk，default vlanid为vlan1，trunk vlanid为空，重复步骤2、3 | N59: 【check1】配置成功 【check2】仪表1、2口分别收到对端发送的报文 【check3】业务中断后正常恢复 | O59: NGFW_V60R1C00 | P59: J1900,C236,EP | T59: 否
D60: MAC学习
E61: 动态MAC
F62: 源MAC为非单播时不学习MAC地址测试 | G62: L2.mac.Dynamic.001 | H62: 1102101 | I62: LEVEL2 | L62: 1、网元正常启动 2、网元GE1、GE2分别连接仪表口1、2，仪表1、2口配置同网段IP | M62: 1、配置GE1和GE2为交换模式，类型为access，vlanid相同【check1】 2、从仪表1口发送源MAC为广播的报文，查看网元是否学习到报文源MAC【check2】 3、从仪表1口发送源MAC为组播的报文，查看网元是否学习到报文源MAC【check2】 4、从仪表1口发送CRC错包的报文，查看网元是否学习到报文源MAC【check2】 | N62: 【check1】配置成功 【check2】网元未学习到表项 | O62: NGFW_V60R1C00 | P62: J1900,C236,EP | T62: 是
...

Sheet 附录1
A1: 统计信息
A2: 用例级别 | B2: 目标占比 | C2: 实际占比
A3: LEVEL0~1 | B3: <15% | C3: =C$9+C$10 -> 0.079365079
A4: LEVEL2~3 | B4: >40% | C4: =C$11+C$12 -> 0.68253968
A5: LEVEL0~3 | B5: >60% | C5: =C$9+C$10+C$11+C$12 -> 0.76190476
A6: 可自动化率 | B6: =E9/SUM(E9:E10) -> 0.88888889
A7: 详细数据
A8: 用例级别 | B8: 数量 | C8: 占比 | D8: 是否自动化 | E8: 数量
A9: LEVEL0 | B9: =COUNTIF(用例全集!$I:$I,A9) -> 4 | C9: =B9/SUM(B$9:B$15) -> 0.063492063 | D9: 是 | E9: =COUNTIF(用例全集!$T:$T,D9) -> 56
A10: LEVEL1 | B10: =COUNTIF(用例全集!$I:$I,A10) -> 1 | C10: =B10/SUM(B$9:B$15) -> 0.015873016 | D10: 否 | E10: =COUNTIF(用例全集!$T:$T,D10) -> 7
A11: LEVEL2 | B11: =COUNTIF(用例全集!$I:$I,A11) -> 28 | C11: =B11/SUM(B$9:B$15) -> 0.44444444
A12: LEVEL3 | B12: =COUNTIF(用例全集!$I:$I,A12) -> 15 | C12: =B12/SUM(B$9:B$15) -> 0.23809524
A13: LEVEL4 | B13: =COUNTIF(用例全集!$I:$I,A13) -> 9 | C13: =B13/SUM(B$9:B$15) -> 0.14285714
A14: LEVEL5 | B14: =COUNTIF(用例全集!$I:$I,A14) -> 4 | C14: =B14/SUM(B$9:B$15) -> 0.063492063
A15: LEVEL6 | B15: =COUNTIF(用例全集!$I:$I,A15) -> 2 | C15: =B15/SUM(B$9:B$15) -> 0.031746032
A16: 总数 | B16: =SUM(B9:B15) -> 63
A19: 用例基线时间点
A20: TR5基线一次 | B20: TR6基线一次
A22: 字段填写说明
A23: 用例编号 | B23: 使用1到4级目录加三位数字，例如SrvQuality.Qos.Classfy.DiffServ001
A24: 用例级别 | B24: 使用LEVEL0~LEVEL6级，定义说明见下表
B25: 用例级别 | C25: 层级描述 | D25: 备注 | F25: 统计说明
B26: LEVEL0 | C26: 配置测试 | D26: 包含配置测试、配置容错测试 | F26: 1、基本用例Level0~Level3占比总用例60%以上；Level0~Level1占总用例不超过15%，Level2~Level3占总用例至少40% 2、Level0、Level2级别的用例可以做自动化用例；Level1、Level3级别的用例争取做自动化
B27: LEVEL1 | C27: 配置可靠性测试 | D27: 包含配置容限测试、Oplog
B28: LEVEL2 | C28: 基本功能测试 | D28: 客户常用功能和常用告警性能
B29: LEVEL3 | C29: 扩展功能测试 | D29: 客户不常用的功能和不常用告警性能
B30: LEVEL4 | C30: 特性可靠性 | D30: 包含单特性的可靠性测试用例。包括反复增删单特性配置、复位重启、拔插单板、网线、主备切换等
B31: LEVEL5 | C31: 特性耦合测试 | D31: 包含两特性耦合和多特性耦合测试用例
B32: LEVEL6 | C32: 特性升级 | D32: 单特性的升级测试用例，包括升级前后配置检查、升级后观察业务、增删配置等
A33: 组网描述 | B33: 必须是用英文的逗号分隔。例如Update01,Update02
A34: 组网约束 | B34: 按实际情况填写
A35: 预置条件 | B35: 按实际情况填写
A36: 测试步骤 | B36: 通常一个用例不超过7步
A37: 预期结果 | B37: 使用check点的方式填写
A38: 适用版本 | B38: 必须以英文逗号分隔,必须使用统一的名称:V1R1C00,V1R1C01
A39: 设备类型* | B39: 必须以英文逗号分隔,J1900,C236,EP
A40: 单板类型 | B40: 必须以英文逗号分隔,
A41: 关键词 | B41: 必须以逗号分隔，公共的关键字必须一致，新增关键字找用例管理员申请
A42: 测试类型* | B42: LEVEL0,LEVEL1-->配置测试；LEVEL2,LEVEL3-->功能测试；LEVEL4-->可靠性测试；LEVL5-->耦合测试；LEVEL6-->升级测试
A43: 是否自动化* | B43: "是"或者"否"
...
