Workbook

Sheet 首页
C4: NGFW V60R001C00 IPv4路由特性测试用例
C15: 拟定 | D15: 赵海波 | F15: 日期 | G15: 44515
C17: 审核 | F17: 日期 | G17: XXXX/XX/XX
C19: 批准 | F19: 日期
E23: 修订记录
C25: 日期 | D25: 修订版本 | E25: 修改记录 | I25: 修改人
C26: 44515 | D26: V1.0 | E26: 初稿输出 | I26: 赵海波

Sheet 测试点分析
A1: 四级目录 | B1: 五级目录 | C1: 测试点 | D1: 测试设计方法 | E1: 适用场景 | F1: 用例规模（个） | G1: 测试数据
A2: 配置管理
B3: 路由配置
A4: 路由维护
B5: 静态路由
C6: 配置静态路由测试 | D6: 等价类划分&数据组合 | F6: 5 | G6: 目的IP地址,掩码长度，权重，优先级，目的IP和下一跳重复
C7: 路由表维护功能测试 | D7: 流程图 | F7: 5 | G7: 出接口IP地址计算静态路由生效和失效,出接口状态计算静态路由生效与失效，默认路由的生效与失效，优先级最高的静态路由生效优先级低的路由不生效，静态路由的出接口为物理口、聚合口、BVI口、L3子接口、Tunnel口,静态路由的下一跳与接口默认网关相同
C8: 容量测试 | D8: 直接分析 | F8: 2 | G8: 最大数量的等价路由,等价路由最大数量的链路数量，最静态路由数量，最大直连路由数量，达到最大数量后的增删测试
C9: HA配置同步 | D9: 直接分析 | F9: 1 | G9: 静态路由配置不同步,主用设备和备用设备都可以配置静态路由
C10: 配置导入导出 | D10: 直接分析 | F10: 3 | G10: 配置导入、导出、配置校验、增量导入
C11: 升级测试 | D11: 直接分析 | F11: 1 | G11: 物理接口、聚合口、L3子接口、BVI接口和Tunnel口的静态路由均能恢复
C12: Oplog测试 | D12: 直接分析 | F12: 1 | G12: 静态路由增加、删除、修改能够记录Oplog，记录的时间、操作者、对象和参数正确
C13: 静态路由性能测试 | D13: 直接分析 | F13: 1 | G13: 配置路由响应时间
C14: 静态路由默认值测试 | D14: 直接分析 | F14: 1 | G14: 优先级和权重
C15: 配置存库测试 | D15: 直接分析 | F15: 1 | G15: 修改配置后快速切换
B16: 直连路由
C17: 直连路由的维护 | D17: 等价类划分&数据组合 | F17: 2 | G17: 物理接口，聚合口、L3子接口、BVI接口、Tunnel口，直连路由根据接口状态计算生效与失效，直连路由的开销
C18: 升级测试 | D18: 直接分析 | F18: 1 | G18: 升级后所有接口能生成直连路由
C19: 容量测试 | D19: 直接分析 | F19: 2 | G19: 最大数量的直连路由，达到最大数量后的增删测试
C20: 反复操作 | D20: 直接分析 | F20: 1 | G20: 反复修改接口IP地址
A21: 业务转发
B22: 路由转发
C23: 路由转发 | D23: 等价类划分&数据组合 | F23: 5 | G23: 出接口为物理接口，聚合口、L3子接口、BVI接口、Tunnel口，静态路由（主机路由，网段路由）、直连路由、默认路由转发、DMAC与接口IP地址相同,DMAC与接口IP地址不同，掩码长度最长匹配，路由转发不匹配优先级
C24: 异常报文检测 | D24: 直接分析 | F24: 2 | G24: SIP为ABC类地址中的广播地址，SIP为D类，SIP为E类，SIP为全F，SIP为127段，SIP为全0
C25: 带VLAN的报文路由转发 | D25: 直接分析 | F25: 1 | G25: 不带VLAN，带VLAN，带两层VLAN
C26: 路由转发时修改配置 | D26: 直接分析 | F26: 2 | G26: 路由增删改查,修改接口IP
C27: 浮动路由测试 | D27: 直接分析 | F27: 3 | G27: 高低优先级路由之间切换、静态路由和直连路由间切换、静态路由和默认路由之间的切换
C28: 路由转发的可靠性 | D28: 直接分析 | F28: 8 | G28: 接口UP、DOWN、掉电。命令复位，反复增删路由，反复修改下一跳，反复启用停用，反复设备掉电，反复设备命令复位
C29: 路由转发业务互不影响 | D29: 直接分析 | F29: 1 | G29: IPv6业务
C30: ARP可靠性测试 | D30: 直接分析 | F30: 3 | G30: ARP不存在到存在，ARP存在到不存在，大量的ARP miss
C31: 高可用场景的路由转发 | D31: 直接分析 | F31: 1 | G31: HA主备切换和回切后路由转发正常
C32: 升级测试 | D32: 直接分析 | F32: 1 | G32: 升级后业务正常
B33: 单臂路由
C34: 不同接口单臂路由转发 | D34: 直接分析 | F34: 3 | G34: 聚合口与L3子接口、物理接口与L3子接口，L3子接口与L3子接口
C35: 相同接口的单臂路由转发 | D35: 直接分析 | F35: 5 | G35: 物理接口、聚合口、L3子接口、BVI接口、Tunnel口
C36: 单臂路由可靠性 | D36: 直接分析 | F36: 1 | G36: 单臂路由转发时增删静态路由
B37: 等价路由
C38: 等价路由维护 | D38: 等价类划分&数据组合 | F38: 5 | G38: 静态路由形成等价路由，默认路由形成等价路由，高优先级路由生效时等价路由失效，高优先级路由失效时等价路由生效，默认路由接口类型（物理接口、聚合口、L3子接口、BVI接口、Tunnel口）
C39: 等价路由业务分担测试 | D39: 等价类划分&数据组合 | F39: 3 | G39: 分担算法测试，修改权重
C40: 等价路由链路切换 | D40: 直接分析 | F40: 4 | G40: 业务切换，新增链路可以分担业务，新增链路老业务不受影响，减少链路，删除非业务转发链路业务不受影响
...

Sheet 测试组网设计
A1: 名称 | B1: NE1_link0
A2: 组网图
A23: 名称 | B23: NE1_ins
A24: 组网图
A45: 名称 | B45: NE1_link4_ins
A46: 组网图
A67: 名称 | B67: NE4_link5_ins
A68: 组网图

Sheet 路由配置
A1: 测试点汇总 | B1: 测试点 | C1: 测试设计方法 | D1: 适用场景 | E1: 用例规模（个） | F1: 测试数据
B2: 新增静态路由测试 | C2: 等价类划分&数据组合 | E2: 8 | F2: 目的IP地址,掩码长度，权重，优先级，目的IP和下一跳重复
B3: 静态路由唯一性测试 | C3: 直接分析 | E3: 1 | F3: 目的网段和下一跳相同
B4: 修改静态路由测试 | C4: 等价类划分&数据组合 | F4: 目的IP，掩码长度，权重，优先级，路由ID不存在
B5: 删除静态路由测试 | C5: 直接分析 | F5: 单条删除，批量删除，路由ID不存在
B6: 容量测试 | C6: 直接分析 | E6: 2 | F6: 最大数量的等价路由,等价路由最大数量的链路数量，最静态路由数量，最大直连路由数量，达到最大数量后的增删测试
B7: Oplog测试 | C7: 直接分析 | E7: 1 | F7: 静态路由增加、删除、修改能够记录Oplog，记录的时间、操作者、对象和参数正确
A8: 添加静态路由测试 | B8: 【设计方法】等价类划分&数据组合
B9: 步骤1:等价类划分
B10: 等价类划分 | C10: 测试数据 | D10: 有效类 | E10: 无效类 | F10: 选取策略 | G10: 选取结果
C11: 目的网络 | D11: 0.0.0.0/0 | E11: 224.0.0.0/[3-32] | F11: 数据名称和分类独立 | G11: 数据名称=目的网络;有效值=0.0.0.0/0,223.255.255.255/32,[1-126].[0-255].[0-255].[0-255]/[1-31],[128-223).[0-255].[0-255].[0-255]/[1-31],[224-255].[0-255].[0-255].[0-255]/[1-2],127.[0-255].[0-255].[0-255]/[1-7];无效值=224.0.0.0/[3-32],127.[0-255].[0-255].[0-255]/[8-32],空,超长字符串,3段点分十进制,5段点分十进制,点分号错误,掩码分隔符错误,16进制IP
D12: 223.255.255.255/32 | E12: 127.[0-255].[0-255].[0-255]/[8-32]
D13: [1-126].[0-255].[0-255].[0-255]/[1-31] | E13: 空
D14: [128-223).[0-255].[0-255].[0-255]/[1-31] | E14: 超长字符串
D15: [224-255].[0-255].[0-255].[0-255]/[1-2] | E15: 3段点分十进制
D16: 127.[0-255].[0-255].[0-255]/[1-7] | E16: 5段点分十进制
E17: 点分号错误
E18: 掩码分隔符错误
E19: 16进制IP
C20: 出接口 | D20: 暂时不分析 | F20: 数据名称和分类独立 | G20: 数据名称=出接口;有效值=暂时不分析
C21: 下一跳 | D21: 1.0.0.0 | E21: 0.[0-255].[0-255].[0-255] | F21: 数据名称和分类独立 | G21: 数据名称=下一跳;有效值=1.0.0.0,223.255.255.255,(1-126].[0-255].[0-255].[0-255],[128-223].[0-255].[0-255].[0-255];无效值=0.[0-255].[0-255].[0-255],224.[0-255].[0-255].[0-255],空,超长字符串,3段点分十进制,5段点分十进制,点分号非".",127.[0-255].[0-255].[0-255],任意接口的IP
D22: 223.255.255.255 | E22: 224.[0-255].[0-255].[0-255]
D23: (1-126].[0-255].[0-255].[0-255] | E23: 空
D24: [128-223].[0-255].[0-255].[0-255] | E24: 超长字符串
E25: 3段点分十进制
E26: 5段点分十进制
E27: 点分号非"."
E28: 127.[0-255].[0-255].[0-255]
E29: 任意接口的IP
C30: 权重 | D30: 1 | E30: 0 | F30: 数据名称和分类独立 | G30: 数据名称=权重;有效值=1.0,(0-255)间任意值,255.0,空;无效值=0.0,256.0,字符串,超长字符串
D31: (0-255)间任意值 | E31: 256
D32: 255 | E32: 字符串
D33: 空 | E33: 超长字符串
C34: 优先级 | D34: 1 | E34: 0 | F34: 数据名称和分类独立 | G34: 数据名称=优先级;有效值=1.0,(1-255)间任意值,255.0,空;无效值=0.0,256.0,字符串,超长字符串
D35: (1-255)间任意值 | E35: 256
D36: 255 | E36: 字符串
D37: 空 | E37: 超长字符串
B38: 步骤2:数据组合
B39: 数据组合 | C39: 测试数据 | D39: 数据取值 | E39: 组合数据分析 | F39: 约束条件和组合策略 | G39: 组合结果
C40: 所有数据不组合
...

Sheet 静态路由
A1: 测试点汇总 | B1: 测试点 | C1: 测试设计方法 | D1: 适用场景 | E1: 用例规模（个） | F1: 测试数据
B2: 配置静态路由测试 | C2: 等价类划分&数据组合 | E2: 8 | F2: 目的IP地址,掩码长度，权重，优先级，目的IP和下一跳重复
B3: 静态路由唯一性测试 | C3: 直接分析 | E3: 1 | F3: 目的网段和下一跳相同
B4: 路由批量删除和查询测试 | C4: 直接分析 | E4: 2 | F4: 查询和删除路由测试
B5: 路由转发表添加条件测试 | C5: 流程图 | E5: 8 | F5: 出接口IP地址计算静态路由生效和失效,出接口状态计算静态路由生效与失效，默认路由的生效与失效，优先级最高的静态路由生效优先级低的路由不生效，静态路由的出接口为物理口、聚合口、BVI口、L3子接口、Tunnel口,静态路由的下一跳与接口默认网关相同
B6: 路由转发表删除条件测试 | C6: 直接分析 | E6: 3 | F6: 修改接口IP,修改下一跳,接口状态变为Down
B7: 路由转发表中的路由切换接口测试 | C7: 直接分析 | E7: 2 | F7: 修改接口IP,修改下一跳,出接口状态变为Down
B8: 路由转发表维护优先级功能验证 | C8: 直接分析 | E8: 2 | F8: 优先级相同,优先级不同
B9: 容量测试 | C9: 直接分析 | E9: 2 | F9: 最大数量的等价路由,等价路由最大数量的链路数量，最静态路由数量，最大直连路由数量，达到最大数量后的增删测试
B10: HA配置同步 | C10: 直接分析 | E10: 1 | F10: 静态路由配置不同步,主用设备和备用设备都可以配置静态路由
B11: 配置导入导出 | C11: 直接分析 | E11: 3 | F11: 配置导入、导出、配置校验、增量导入
B12: 升级测试 | C12: 直接分析 | E12: 1 | F12: 物理接口、聚合口、L3子接口、BVI接口和Tunnel口的静态路由均能恢复
B13: Oplog测试 | C13: 直接分析 | E13: 1 | F13: 静态路由增加、删除、修改能够记录Oplog，记录的时间、操作者、对象和参数正确
... B16: 配置存库测试 | C16: 直接分析 | E16: 1 | F16: 修改配置后快速切换
A17: 路由转发表添加条件测试 | B17: 【设计方法】流程图法
B18: 步骤1:流程图
B20: 步骤2:测试路径分析
B21: 路径编号 | C21: 路径覆盖 | E21: 路径描述
B22: path1 | C22: P1-P2-P4 | E22: 配置静态路由-下一跳直接匹配接口-接口状态UP-生成路由转发表
B23: path2 | C23: P1-P3-P4 | E23: 配置静态路由-下一跳不匹配接口-接口配置IP后静态路由匹配接口-接口状态UP-生成路由转发表
B24: path3 | C24: P1-P2-P5 | E24: 配置静态路由-下一跳直接匹配接口-无路由-接口状态UP-生成路由转发表
B25: path4 | C25: P1-P5-P5 | E25: 配置静态路由-下一跳不匹配接口-接口配置IP后静态路由匹配接口-接口为UP-无路由转发表-接口状态UP后生成路由转发表
B26: 步骤3:等价类划分
B27: 等价类划分 | C27: 测试数据 | D27: 有效类 | E27: 无效类
C28: 接口类型 | D28: 物理接口 | F28: 划分方法：无 选取策略：全选 选取结果：接口类型=物理接口,聚合接口口,L3子接口,BVI接口
D29: 聚合接口口
D30: L3子接口
D31: BVI接口
D32: #Tunnel口
C33: 目的网段 | D33: 0.0.0.0/0 | F33: 划分方法：无 选取策略：全选 选取结果：目的网段=0.0.0.0/0,223.255.255.255/32,[1-126].[0-255].[0-255].[0-255]/[1-31],[128-223).[0-255].[0-255].[0-255]/[1-31]
D34: 223.255.255.255/32
D35: [1-126].[0-255].[0-255].[0-255]/[1-31]
D36: [128-223).[0-255].[0-255].[0-255]/[1-31]
C37: 下一跳 | D37: 1.0.0.0 | F37: 划分方法：无 选取策略：全选 选取结果：下一跳=1.0.0.0,223.255.255.255,(1-126].[0-255].[0-255].[0-255],[128-223].[0-255].[0-255].[0-255]
D38: 223.255.255.255
D39: (1-126].[0-255].[0-255].[0-255]
D40: [128-223].[0-255].[0-255].[0-255]
C41: 权重 | D41: 0 | F41: 划分方法：无 选取策略：全选 选取结果：权重=0,(0-255)间任意值,255,空
D42: (0-255)间任意值
D43: 255
...

Sheet 直连路由
A1: 测试点汇总 | B1: 测试点 | C1: 测试设计方法 | D1: 适用场景 | E1: 用例规模（个） | F1: 测试数据
B2: 直连路由的维护 | C2: 等价类划分&数据组合 | E2: 2 | F2: 物理接口，聚合口、L3子接口、BVI接口、Tunnel口，直连路由根据接口状态计算生效与失效，直连路由的开销
B3: 直连路由的维护-多接口IP | C3: 直接分析 | E3: 1 | F3: 多个接口IP
B4: 直连路由的维护-成员接口状态 | C4: 直接分析 | E4: 2 | F4: 聚合接口，BVI接口
B5: 直连路由的维护-逻辑接口增删 | C5: 直接分析 | E5: 1 | F5: 聚合口、L3子接口、BVI接口
B6: 升级测试 | C6: 直接分析 | E6: 1 | F6: 升级后所有接口能生成直连路由
B7: 容量测试 | C7: 直接分析 | E7: 2 | F7: 最大数量的直连路由，达到最大数量后的增删测试
B8: 反复操作 | C8: 直接分析 | E8: 1 | F8: 反复修改接口IP地址
A9: 直连路由的维护 | B9: 【设计方法】等价类划分&数据组合
B10: 步骤1:等价类划分
B11: 等价类划分 | C11: 测试数据 | D11: 有效类 | E11: 无效类
C12: 接口类型IP | D12: 128.0.0.1/2 | F12: 划分方法：无 选取策略：全选 选取结果：接口IP=128.0.0.1/2,233.255.255.254/30,1.0.0.1/30,首段为(1~126]的任意有效值,首段为[128-223)的任意有效值
D13: 233.255.255.254/30
D14: 1.0.0.1/30
D15: 首段为(1~126]的任意有效值
D16: 首段为[128-223)的任意有效值
C17: 接口类型 | D17: 物理接口 | F17: 划分方法：无 选取策略：全选 选取结果：接口类型=物理接口,聚合接口,L3子接口,BVI接口
D18: 聚合接口
D19: L3子接口
D20: BVI接口
D21: #Tunnel口
D22: #PPPoE接口
B23: 步骤2:数据组合
B24: 数据组合 | C24: 测试数据 | D24: 数据取值 | E24: 组合数据分析 | F24: 约束条件和组合策略 | G24: 组合结果
C25: 接口类型 | D25: 物理接口 | E25: 接口类型IP | F25: 接口IP=128.0.0.1/2,首段为(1~126]的任意有效值 | G25: 接口类型=物理接口;接口IP=128.0.0.1/2,首段为(1~126]的任意有效值
D26: 聚合接口 | E26: 接口类型IP | F26: 接口IP=233.255.255.254/30 | G26: 接口类型=聚合接口;接口IP=233.255.255.254/30
D27: L3子接口 | E27: 接口类型IP | F27: 接口IP=1.0.0.1/30 | G27: 接口类型=L3子接口;接口IP=1.0.0.1/30
D28: BVI接口 | E28: 接口类型IP | F28: 接口IP=首段为[128-223)的任意有效值 | G28: 接口类型=BVI接口;接口IP=首段为[128-223)的任意有效值
B29: 步骤3:逻辑用例设计
B30: 逻辑用例编号 | C30: 测试用例描述 | F30: 覆盖的测试数据 | G30: 测试数据选取结果
B31: ipv4.direct.route.fib.phyintf | C31: 验证接口IP生成直连路由功能 | F31: 接口类型&接口IP | G31: 接口类型=物理接口;接口IP=128.0.0.1/2,首段为(1~126]的任意有效值 接口类型=聚合接口;接口IP=233.255.255.254/30 接口类型=L3子接口;接口IP=1.0.0.1/30 接口类型=BVI接口;接口IP=首段为[128-223)的任意有效值
B32: 步骤4:物理用例设计
B33: 逻辑用例编号 | C33: 用例标题 | D33: 测试数据 | E33: 预置条件 | F33: 测试步骤 | G33: 预期结果
B34: ipv4.direct.route.fib | C34: 验证${接口类型}的IP地址生成直连路由功能 | D34: 接口类型=物理接口;接口IP=128.0.0.1/2,首段为(1~126]的任意有效值 接口类型=聚合接口;接口IP=233.255.255.254/30 接口类型=L3子接口;接口IP=1.0.0.1/30 接口类型=BVI接口;接口IP=首段为[128-223)的任意有效值 | E34: 网元正常启动 | F34: 1、配置${接口类型}为路由模式 2、配置接口的IP地址为$[接口IP]，并观察路由转发表【check1】 3、构造接口状态为Down，观察路由转发表【check2】 | G34: 【check1】配置成功，路由转发表中生成接口IP所在网段的直连路由 【check2】接口IP生成的直连路由消失
A35: 直连路由维护-接口多IP | B35: 【设计方法】直接设计法
B36: 步骤1:逻辑用例设计
B37: 逻辑用例编号 | C37: 测试用例描述 | F37: 覆盖的测试数据 | G37: 测试数据选取结果
B38: ipv4.direct.route.fib.mulip | C38: 验证接口多IP均能生成直连路由 | G38: 接口类型=物理接口,聚合接口,L3子接口,BVI接口
B39: 步骤2:物理用例设计
B40: 逻辑用例编号 | C40: 用例标题 | D40: 测试数据 | E40: 预置条件 | F40: 测试步骤 | G40: 预期结果
...

Sheet 路由转发
A1: 测试点汇总 | B1: 测试点 | C1: 测试设计方法 | D1: 适用场景 | E1: 用例规模（个） | F1: 测试数据
B2: 静态路由转发 | C2: 等价类划分&数据组合 | E2: 4 | F2: 出接口为物理接口，聚合口、L3子接口、BVI接口、Tunnel口，静态路由（主机路由，网段路由）、直连路由、默认路由转发、DMAC与接口IP地址相同,DMAC与接口IP地址不同，掩码长度最长匹配，路由转发不匹配优先级
B3: 直连路由转发 | C3: 等价类划分&数据组合 | E3: 4 | F3: 出接口为物理接口，聚合口、L3子接口、BVI接口、Tunnel口，静态路由（主机路由，网段路由）、直连路由、默认路由转发、DMAC与接口IP地址相同,DMAC与接口IP地址不同，掩码长度最长匹配，路由转发不匹配优先级
B4: 掩码最长匹配 | C4: 直接分析 | E4: 2 | F4: 掩码长度最长匹配，路由转发不匹配优先级
B5: 异常报文检测 | C5: 直接分析 | E5: 2 | F5: SIP为ABC类地址中的广播地址，SIP为D类，SIP为E类，SIP为全F，SIP为127段，SIP为全0
B6: 带VLAN的报文路由转发 | C6: 直接分析 | E6: 1 | F6: 不带VLAN，带VLAN，带两层VLAN
B7: 路由转发时修改配置 | C7: 直接分析 | E7: 2 | F7: 路由增删改查,修改接口IP
B8: 浮动路由业务切换测试 | C8: 直接分析 | E8: 3 | F8: 高低优先级路由之间切换、静态路由和直连路由间切换、静态路由和默认路由之间的切换
B9: 路由转发的可靠性 | C9: 直接分析 | E9: 8 | F9: 接口UP、DOWN、掉电。命令复位，反复增删路由，反复修改下一跳，反复启用停用，反复设备掉电，反复设备命令复位
B10: 路由转发业务互不影响 | C10: 直接分析 | E10: 1 | F10: IPv6业务
B11: ARP可靠性测试 | C11: 直接分析 | E11: 3 | F11: ARP不存在到存在，ARP存在到不存在，大量的ARP miss
B12: 高可用场景的路由转发 | C12: 直接分析 | E12: 1 | F12: HA主备切换和回切后路由转发正常
B13: 升级测试 | C13: 直接分析 | E13: 1 | F13: 升级后业务正常
A14: 静态路由转发 | B14: 【设计方法】等价类划分&数据组合
B15: 步骤1:等价类划分
B16: 等价类划分 | C16: 测试数据 | D16: 有效类 | E16: 无效类
C17: 目的网段 | D17: 0.0.0.0/0 | F17: 划分方法：无 选取策略：全选 选取结果：目的网段=0.0.0.0/0,223.255.255.255/32,[1-126].[0-255].[0-255].[0-255]/[1-31],[128-223).[0-255].[0-255].[0-255]/[1-31]
D18: 223.255.255.255/32
D19: [1-126].[0-255].[0-255].[0-255]/[1-31]
D20: [128-223).[0-255].[0-255].[0-255]/[1-31]
C21: 出接口类型 | D21: 物理接口 | F21: 划分方法：无 选取策略：全选 选取结果：接口类型=物理接口,聚合接口,L3子接口,BVI接口
D22: 聚合接口
D23: L3子接口
D24: BVI接口
D25: #Tunnel口
D26: #PPPoE接口
C27: 下一跳 | D27: 1.0.0.0 | F27: 划分方法：无 选取策略：全选 选取结果：下一跳=1.0.0.0,223.255.255.255,(1-126].[0-255].[0-255].[0-255],[128-223].[0-255].[0-255].[0-255]
D28: 223.255.255.255
D29: (1-126].[0-255].[0-255].[0-255]
D30: [128-223].[0-255].[0-255].[0-255]
B31: 步骤2:数据组合
B32: 数据组合 | C32: 测试数据 | D32: 数据取值 | E32: 组合数据分析 | F32: 约束条件和组合策略 | G32: 组合结果
C33: 接口类型 | D33: 物理接口 | E33: 目的网段&下一跳 | F33: 所有取值至少出现一次 | G33: 接口类型=物理接口;目的网段=0.0.0.0/0;权重=0;优先级=1;下一跳=1.0.0.0
D34: 聚合接口 | E34: 目的网段&下一跳 | F34: 所有取值至少出现一次 | G34: 接口类型=聚合接口;目的网段=,[1-126].[0-255].[0-255].[0-255]/[1-31];权重=255;优先级=255;下一跳=223.255.255.255
D35: L3子接口 | E35: 目的网段&下一跳 | F35: 所有取值至少出现一次 | G35: 接口类型=L3子接口;目的网段=[128-223).[0-255].[0-255].[0-255]/[1-31];权重=空;优先级=空;;下一跳=[128-223].[0-255].[0-255].[0-255]
D36: BVI接口 | E36: 目的网段&下一跳 | F36: 所有取值至少出现一次 | G36: 接口类型=BVI接口;目的网段=223.255.255.255/32;权重=(0-255)间任意值;优先级=(1-255)间任意值;下一跳=(1-126].[0-255].[0-255].[0-255]
B37: 步骤3:逻辑用例设计
B38: 逻辑用例编号 | C38: 测试用例描述 | F38: 覆盖的测试数据 | G38: 测试数据选取结果
B39: ipv4.fwd.static | C39: 验证静态路由转发 | F39: 接口类型&接口IP | G39: 接口类型=物理接口;目的网段=0.0.0.0/0;权重=0;优先级=1;下一跳=1.0.0.0 接口类型=聚合接口;目的网段=,[1-126].[0-255].[0-255].[0-255]/[1-31];权重=255;优先级=255;下一跳=223.255.255.255 接口类型=BVI接口;目的网段=223.255.255.255/32;权重=(0-255)间任意值;优先级=(1-255)间任意值;下一跳=(1-126].[0-255].[0-255].[0-255] 接口类型=L3子接口;目的网段=[128-223).[0-255].[0-255].[0-255]/[1-31];权重=空;优先级=空;;下一跳=[128-223].[0-255].[0-255].[0-255]
B40: 步骤4:物理用例设计
...

Sheet 单臂路由
A1: 测试点汇总 | B1: 测试点 | C1: 测试设计方法 | D1: 适用场景 | E1: 用例规模（个） | F1: 测试数据
B2: 不同类型接口单臂路由转发 | C2: 直接分析 | E2: 3 | F2: 聚合口与L3子接口、物理接口与L3子接口，L3子接口与L3子接口
B3: 相同类型接口的单臂路由转发 | C3: 直接分析 | E3: 5 | F3: 物理接口、聚合口、L3子接口、BVI接口、Tunnel口
B4: 单臂路由可靠性 | C4: 直接分析 | E4: 1 | F4: 单臂路由转发时增删静态路由
B5: 单臂路由与策略耦合 | C5: 直接分析 | E5: 1 | F5: 单臂路由与默认策略耦合
A6: 不同接口单臂路由转发 | B6: 【设计方法】直接设计法
B7: 步骤1:逻辑用例设计
B8: 逻辑用例编号 | C8: 测试用例描述 | F8: 覆盖的测试数据 | G8: 测试数据选取结果
B9: IPv4.single.arm.diff.intf | C9: 验证${接口}间的单臂路由转发 | F9: 不涉及 | G9: 接口=聚合口与L3子接口,物理接口与L3子接口,L3子接口与L3子接口
B10: 步骤2:物理用例设计
B11: 逻辑用例编号 | C11: 用例标题 | D11: 测试数据 | E11: 预置条件 | F11: 测试步骤 | G11: 预期结果
B12: IPv4.single.arm.diff.intf | C12: 验证${接口描述}间的单臂路由转发 | D12: 接口描述=聚合口与L3子接口;预配置=配置聚合口和该聚合口上创建的L3子接口的IP分别匹配这两条静态路由 接口描述=物理接口与L3子接口;预配置=配置物理接口和该物理接口上创建的L3子接口的IP分别匹配这两条静态路由 接口描述=L3子接口与L3子接口;预配置=配置同一物理接口或者聚合口上的两个L3子接口的IP分别匹配这两条静态路由 | E12: 1、网元正常启动 2、配置默认转发策略为允许 | F12: 1、配置两条静态路由。 2、${预配置} 3、在${接口描述}之间双向发送匹配静态路由的报文，观察报文转发。【check1】 | G12: 【check1】报文正常转发，封装的DMAC、SMAC正确，无丢包。
A13: 相同接口单臂路由转发 | B13: 【设计方法】直接设计法
B14: 步骤1:逻辑用例设计
B15: 逻辑用例编号 | C15: 测试用例描述 | F15: 覆盖的测试数据 | G15: 测试数据选取结果
B16: IPv4.single.arm.same.intf | C16: 验证${接口}内的单臂路由转发 | F16: 不涉及 | G16: 接口=物理接口,聚合口,L3子接口,BVI接口
B17: 步骤2:物理用例设计
B18: 逻辑用例编号 | C18: 用例标题 | D18: 测试数据 | E18: 预置条件 | F18: 测试步骤 | G18: 预期结果
B19: IPv4.single.arm.same.intf | C19: 验证${接口}内的单臂路由转发 | D19: 接口=物理接口,聚合口,L3子接口,BVI接口 | E19: 1、网元正常启动 2、配置默认转发策略为允许 | F19: 1、配置两条静态路由，下一跳不同但在相同网段。 2、配置${接口}的IP与这两条静态的下一跳在相同网段 3、向${接口}之发送配匹配这两条静态路由的报文，观察报文转发。【check1】 | G19: 【check1】报文正常转发，封装的DMAC、SMAC正确，无丢包。
A20: 单臂路由可靠性 | B20: 【设计方法】直接设计法
B21: 步骤1:逻辑用例设计
B22: 逻辑用例编号 | C22: 测试用例描述 | F22: 覆盖的测试数据 | G22: 测试数据选取结果
B23: IPv4.single.arm.reliability | C23: 验证反复增删静态路由对单臂路由转发的影响 | F23: 不涉及 | G23: 操作=反复增删静态路由
B24: 步骤2:物理用例设计
B25: 逻辑用例编号 | C25: 用例标题 | D25: 测试数据 | E25: 预置条件 | F25: 测试步骤 | G25: 预期结果
B26: IPv4.single.arm.reliability | C26: 验证反复增删静态路由对单臂路由转发的影响 | D26: 操作=反复增删静态路由 | E26: 1、网元正常启动 2、配置默认转发策略为允许 | F26: 1、配置两条静态路由，出口形成单臂转发（出接口在相同的接口，或者出接口在同一接口上创建的不同子接口）。 2、双向发送匹配静态路由的报文，观察报文转发【check1】 3、反复增删静态路由10次以上，保持路由为删除，观察报文转发。【check2】 4、添加静态路由，观察报文转发。【check1】 | G26: 【check1】报文正常转发，封装的DMAC、SMAC正确，无丢包。 【check2】报文转发中断
A27: 单臂路由与策略耦合 | B27: 【设计方法】直接设计法
B28: 步骤1:逻辑用例设计
B29: 逻辑用例编号 | C29: 测试用例描述 | F29: 覆盖的测试数据 | G29: 测试数据选取结果
B30: IPv4.single.arm.acl | C30: 验证默认策略限制单臂路由转发功能 | F30: 不涉及 | G30: 策略类型=默认策略
B31: 步骤2:物理用例设计
B32: 逻辑用例编号 | C32: 用例标题 | D32: 测试数据 | E32: 预置条件 | F32: 测试步骤 | G32: 预期结果
B33: IPv4.single.arm.acl | C33: 验证默认策略限制单臂路由转发功能 | D33: 操作=反复增删静态路由 | E33: 1、网元正常启动 2、配置默认转发策略为允许 | F33: 1、配置两条静态路由，出口形成单臂转发（出接口在相同的接口，或者出接口在同一接口上创建的不同子接口）。 2、双向发送匹配静态路由的报文，观察报文转发【check1】 3、配置默认策略为阻塞，观察报文转发。【check2】 4、配置默认策略为允许，观察报文转发。【check1】 | G33: 【check1】报文正常转发，封装的DMAC、SMAC正确，无丢包。 【check2】报文转发中断

Sheet 等价路由
A1: 测试点汇总 | B1: 测试点 | C1: 测试设计方法 | D1: 适用场景 | E1: 用例规模（个） | F1: 测试数据
B2: 等价路由维护 | C2: 等价类划分&数据组合 | E2: 5 | F2: 静态路由形成等价路由，默认路由形成等价路由，高优先级路由生效时等价路由失效，高优先级路由失效时等价路由生效，默认路由接口类型（物理接口、聚合口、L3子接口、BVI接口、Tunnel口）
B3: 默认路由与接口网关生成等价路由 | C3: 直接分析 | E3: 1 | F3: 物理接口,聚合口,L3子接口,BVI接口
B4: 等价路由业务分担测试 | C4: 等价类划分&数据组合 | E4: 3 | F4: 分担算法测试，修改权重，默认网关的默认权重分担
B5: 等价路由链路切换 | C5: 直接分析 | E5: 4 | F5: 业务切换，新增链路可以分担业务，新增链路老业务不受影响，减少链路，删除非业务转发链路业务不受影响（不支持）
B6: 静态路由和等价路由间切换 | C6: 直接分析 | E6: 4 | F6: 等价路由和静态路由切换，修改优先级
B7: 等价路由可靠性 | C7: 直接分析 | E7: 4 | F7: 反复链路振荡10次以上,反复修改链路权重10次以上，反复进行设备掉电10次，反复进行设备命令复位10次以上，
B8: 等价路由性能测试 | C8: 直接分析 | E8: 1 | F8: 等价路由链路切换时间
A9: 等价路由维护 | B9: 【设计方法】等价类划分&数据组合
B10: 步骤1:等价类划分
B11: 等价类划分 | C11: 测试数据 | D11: 有效类 | E11: 无效类
C12: 路由类型 | D12: 默认路由 | F12: 划分方法：无 选取策略：全选 选取结果：路由类型=静态路由,默认路由
D13: 静态路由
C14: 出接口类型 | D14: 物理接口 | F14: 划分方法：无 选取策略：全选 选取结果：接口类型=物理接口,聚合接口,L3子接口,BVI接口
D15: 聚合接口
D16: L3子接口
D17: BVI接口
D18: #Tunnel口
D19: #PPPoE接口
B20: 步骤2:数据组合
B21: 数据组合 | C21: 测试数据 | D21: 数据取值 | E21: 组合数据分析 | F21: 约束条件和组合策略 | G21: 组合结果
C22: 路由类型 | D22: 默认路由 | E22: 出接口类型 | F22: 接口类型=物理接口,聚合接口,L3子接口,BVI接口 | G22: 路由类型=默认路由;接口类型=物理接口,聚合接口,L3子接口,BVI接口
D23: 静态路由 | E23: 出接口类型 | F23: 接口类型=物理接口,聚合接口,L3子接口,BVI接口 | G23: 路由类型=静态路由;接口类型=物理接口,聚合接口,L3子接口,BVI接口
B24: 步骤3:逻辑用例设计
B25: 逻辑用例编号 | C25: 测试用例描述 | F25: 覆盖的测试数据 | G25: 测试数据选取结果
B26: ipv4.ecmp.fib | C26: 验证等价路由功能 | F26: 接口类型&接口IP | G26: 路由类型=默认路由;接口类型=物理接口,聚合接口,L3子接口,BVI接口 路由类型=静态路由;接口类型=物理接口,聚合接口,L3子接口,BVI接口
B27: 步骤4:物理用例设计
B28: 逻辑用例编号 | C28: 用例标题 | D28: 测试数据 | E28: 预置条件 | F28: 测试步骤 | G28: 预期结果
B29: ipv4.ecmp.fib | C29: 验证${路由类型}生成等价路由功能 | D29: 路由类型=默认路由;接口类型=物理接口,聚合接口,L3子接口,BVI接口 路由类型=静态路由;接口类型=物理接口,聚合接口,L3子接口,BVI接口 | E29: 网元正常启动 | F29: 1、在网元上配置${接口类型}的IP地址 2、配置多条网络地址相同，优先级相同的静态路由，路由的下一跳分别匹配${接口类型} 3、查看路由转发表【check1】 4、配置一跳优先级更优（优先级取值跟小）的${路由类型}，观察路由转发表。【check2】 5、删除步骤4中配置的静态路由，观察路由转发表。【check1】 | G29: 【check1】路由转发表中步骤2配置的所有下一跳均生效，并形成等价路由。 【check2】路由转发表中的等价路由所有的下一跳全部失效，只有新配置的静态路由生效。
A30: 默认路由与接口网关生成等价路由 | B30: 【设计方法】直接设计法
B31: 步骤1:逻辑用例设计
B32: 逻辑用例编号 | C32: 测试用例描述 | F32: 覆盖的测试数据 | G32: 测试数据选取结果
B33: ipv4.ecmp.fib.gateway | C33: 验证静态默认路由与接口的默认网关生成等价路由 | F33: 不涉及 | G33: 接口=物理接口,聚合口,L3子接口,BVI接口
B34: 步骤2:物理用例设计
B35: 逻辑用例编号 | C35: 用例标题 | D35: 测试数据 | E35: 预置条件 | F35: 测试步骤 | G35: 预期结果
B36: ipv4.ecmp.fib.gateway | C36: 验证默认路由与接口网关生成等价路由功能 | D36: 接口=物理接口,聚合口,L3子接口,BVI接口 | E36: 1、网元正常启动 | F36: 1、配置物理接口、聚合口、L3子接口和BVI接口的IP地址和默认网关，默认网关和本接口IP在相同网段。 2、配置一条默认路由，其优先级与接口默认网关生成的路由的优先级相同。观察路由转发表。【check1】 3、配置静态路由的优先级优于接口默认网关生成的路由（优先级值越小越优），观察路由转发表【check2】 3、配置静态路由的优先级劣于接口默认网关生成的路由。观察路由转发表【check3】 | G36: 【check1】静态路由与所有接口的默认网关路由生成一条等价路由 【check2】所有接口默认网关生成的路由失效，只有静态默认路由生效。 【check3】所有接口默认网关生成的路由生效并形成等价路由，静态默认路由失效。
A37: 等价路由业务分担测试 | B37: 【设计方法】直接设计法
B38: 步骤1:逻辑用例设计
B39: 逻辑用例编号 | C39: 测试用例描述 | F39: 覆盖的测试数据 | G39: 测试数据选取结果
B40: ipv4.ecmp.loadbalance1 | C40: 验证等价路由业务分担功能 | F40: 不涉及 | G40: 路由类型=静态路由
...

Sheet 用例全集
A1: 一级目录 | B1: 二级目录 | C1: 三级目录 | D1: 四级目录 | E1: 五级目录 | F1: 用例名称* | G1: 用例编号 | H1: 用例ID* | I1: 用例级别* | J1: 组网描述* | K1: 组网约束 | L1: 预置条件 | M1: 测试步骤* | N1: 预期结果* | O1: 适用版本* | P1: 设备类型* | Q1: 单板类型 | R1: 关键词 | S1: 测试类型* | T1: 是否自动化* | U1: 需求编号 | V1: 备注 | AH1: LEVEL0 | AI1: LEVEL1 | AJ1: LEVEL2 | AK1: LEVEL3 | AL1: LEVEL4 | AM1: LEVEL5 | AN1: LEVEL6 | AP1: 配置测试 | AQ1: 功能测试 | AR1: 耦合测试 | AS1: 可靠性测试 | AT1: 性能测试 | AU1: 升级测试
A2: 网络特性
B3: IP单播
C4: IPv4路由
D5: 配置管理
E6: 路由配置
F7: 验证添加静态路由时配置目的网络有效值和无效值测试 | G7: ipv4.static.route.add.ptc0 | H7: 1200101 | I7: LEVEL0 | J7: NE1_link0 | L7: 网元正常启动 | M7: 1、使用/api/v1/route接口添加静态路由时，配置目的网络为0.0.0.0/0，其他参数为任意有效值,查询静态路由【check1】 2、使用/api/v1/route接口添加静态路由时，配置目的网络为223.255.255.255/32，其他参数为任意有效值,查询静态路由【check1】 3、使用/api/v1/route接口添加静态路由时，配置目的网络为[1-126].[0-255].[0-255].[0-255]/[1-31]，其他参数为任意有效值,查询静态路由【check1】 4、使用/api/v1/route接口添加静态路由时，配置目的网络为[128-223).[0-255].[0-255].[0-255]/[1-31]，其他参数为任意有效值,查询静态路由【check1】 5、使用/api/v1/route接口添加静态路由时，配置目的网络为[224-255].[0-255].[0-255].[0-255]/[1-2]，其他参数为任意有效值,查询静态路由【check1】 6、使用/api/v1/route接口添加静态路由时，配置目的网络为127.[0-255].[0-255].[0-255]/[1-7]，其他参数为任意有效值,查询静态路由【check1】 7、添加静态路由时，配置目的网络为224.0.0.0/[3-32]，其他参数为任意有效值,查询静态路由【check2】 8、添加静态路由时，配置目的网络为127.[0-255].[0-255].[0-255]/[8-32]，其他参数为任意有效值,查询静态路由【check2】 9、添加静态路由时，配置目的网络为空，其他参数为任意有效值,查询静态路由【check2】 10、添加静态路由时，配置目的网络为超长字符串，其他参数为任意有效值,查询静态路由【check2】 11、添加静态路由时，配置目的网络为3段点分十进制，其他参数为任意有效值,查询静态路由【check2】 12、添加静态路由时，配置目的网络为5段点分十进制，其他参数为任意有效值,查询静态路由【check2】 13、添加静态路由时，配置目的网络为点分号错误，其他参数为任意有效值,查询静态路由【check2】 14、添加静态路由时，配置目的网络为掩码分隔符错误，其他参数为任意有效值,查询静态路由【check2】 15、添加静态路由时，配置目的网络为16进制IP，其他参数为任意有效值,查询静态路由【check2】 | N7: 【check1】配置成功，使用restful查询静态路由与下发的配置相同。使用etcd查询/vnf-agent/vpp1/config/linux/l3/v2/routes/<dip>/<掩码>/preference/<优先级>，查询的值与配置的值相同 【check2】配置失败，网元无异常。使用etcd查询/vnf-agent/vpp1/config/linux/l3/v2/routes/<dip>/<掩码>/preference/<优先级>，查询添加失败的路由不存在 | O7: NGFW_V60R1C00 | P7: J1900,C236,EP | R7: 预测试 | S7: 配置测试 | T7: 是
F8: 验证添加静态路由时配置下一跳有效值和无效值测试 | G8: ipv4.static.route.add.ptc1 | H8: 1200102 | I8: LEVEL0 | J8: NE1_link0 | L8: 网元正常启动 | M8: 1、使用/api/v1/route接口添加静态路由时，配置下一跳为1.0.0.0，其他参数为任意有效值,查询静态路由【check1】 2、使用/api/v1/route接口添加静态路由时，配置下一跳为223.255.255.255，其他参数为任意有效值,查询静态路由【check1】 3、使用/api/v1/route接口添加静态路由时，配置下一跳为(1-126].[0-255].[0-255].[0-255]，其他参数为任意有效值,查询静态路由【check1】 4、使用/api/v1/route接口添加静态路由时，配置下一跳为[128-223].[0-255].[0-255].[0-255]，其他参数为任意有效值,查询静态路由【check1】 5、添加静态路由时，配置下一跳为0.[0-255].[0-255].[0-255]，其他参数为任意有效值,查询静态路由【check2】 6、添加静态路由时，配置下一跳为224.[0-255].[0-255].[0-255]，其他参数为任意有效值,查询静态路由【check2】 7、添加静态路由时，配置下一跳为空，其他参数为任意有效值,查询静态路由【check2】 8、添加静态路由时，配置下一跳为超长字符串，其他参数为任意有效值,查询静态路由【check2】 9、添加静态路由时，配置下一跳为3段点分十进制，其他参数为任意有效值,查询静态路由【check2】 10、添加静态路由时，配置下一跳为5段点分十进制，其他参数为任意有效值,查询静态路由【check2】 11、添加静态路由时，配置下一跳为点分号非"."，其他参数为任意有效值,查询静态路由【check2】 12、添加静态路由时，配置下一跳为127.[0-255].[0-255].[0-255]，其他参数为任意有效值,查询静态路由【check2】 13、添加静态路由时，配置下一跳为任意接口的IP，其他参数为任意有效值,查询静态路由【check2】 | N8: 【check1】配置成功，使用restful查询静态路由与下发的配置相同。使用etcd查询/vnf-agent/vpp1/config/linux/l3/v2/routes/<dip>/<掩码>/preference/<优先级>，查询的值与配置的值相同 【check2】配置失败，网元无异常。使用etcd查询/vnf-agent/vpp1/config/linux/l3/v2/routes/<dip>/<掩码>/preference/<优先级>，查询添加失败的路由不存在 | O8: NGFW_V60R1C00 | P8: J1900,C236,EP | S8: 配置测试 | T8: 是
F9: 验证添加静态路由时配置权重有效值和无效值测试 | G9: ipv4.static.route.add.ptc2 | H9: 1200103 | I9: LEVEL0 | J9: NE1_link0 | L9: 网元正常启动 | M9: 1、使用/api/v1/route接口添加静态路由时，配置权重为1.0，其他参数为任意有效值,查询静态路由【check1】 2、使用/api/v1/route接口添加静态路由时，配置权重为(0-255)间任意值，其他参数为任意有效值,查询静态路由【check1】 3、使用/api/v1/route接口添加静态路由时，配置权重为255.0，其他参数为任意有效值,查询静态路由【check1】 4、使用/api/v1/route接口添加静态路由时，配置权重为空，其他参数为任意有效值,查询静态路由【check1】 5、添加静态路由时，配置权重为0.0，其他参数为任意有效值,查询静态路由【check2】 6、添加静态路由时，配置权重为256.0，其他参数为任意有效值,查询静态路由【check2】 7、添加静态路由时，配置权重为字符串，其他参数为任意有效值,查询静态路由【check2】 8、添加静态路由时，配置权重为超长字符串，其他参数为任意有效值,查询静态路由【check2】 | N9: 【check1】配置成功，使用restful查询静态路由与下发的配置相同。使用etcd查询/vnf-agent/vpp1/config/linux/l3/v2/routes/<dip>/<掩码>/preference/<优先级>，查询的值与配置的值相同 【check2】配置失败，网元无异常。使用etcd查询/vnf-agent/vpp1/config/linux/l3/v2/routes/<dip>/<掩码>/preference/<优先级>，查询添加失败的路由不存在 | O9: NGFW_V60R1C00 | P9: J1900,C236,EP | S9: 配置测试 | T9: 是
F10: 验证添加静态路由时配置优先级有效值和无效值测试 | G10: ipv4.static.route.add.ptc3 | H10: 1200104 | I10: LEVEL0 | J10: NE1_link0 | L10: 网元正常启动 | M10: 1、使用/api/v1/route接口添加静态路由时，配置优先级为1.0，其他参数为任意有效值,查询静态路由【check1】 2、使用/api/v1/route接口添加静态路由时，配置优先级为(1-255)间任意值，其他参数为任意有效值,查询静态路由【check1】 3、使用/api/v1/route接口添加静态路由时，配置优先级为255.0，其他参数为任意有效值,查询静态路由【check1】 4、使用/api/v1/route接口添加静态路由时，配置优先级为空，其他参数为任意有效值,查询静态路由【check1】 5、添加静态路由时，配置优先级为0.0，其他参数为任意有效值,查询静态路由【check2】 6、添加静态路由时，配置优先级为256.0，其他参数为任意有效值,查询静态路由【check2】 7、添加静态路由时，配置优先级为字符串，其他参数为任意有效值,查询静态路由【check2】 8、添加静态路由时，配置优先级为超长字符串，其他参数为任意有效值,查询静态路由【check2】 | N10: 【check1】配置成功，使用restful查询静态路由与下发的配置相同。使用etcd查询/vnf-agent/vpp1/config/linux/l3/v2/routes/<dip>/<掩码>/preference/<优先级>，查询的值与配置的值相同 【check2】配置失败，网元无异常。使用etcd查询/vnf-agent/vpp1/config/linux/l3/v2/routes/<dip>/<掩码>/preference/<优先级>，查询添加失败的路由不存在 | O10: NGFW_V60R1C00 | P10: J1900,C236,EP | S10: 配置测试 | T10: 是
F11: 验证添加静态路由唯一性测试 | G11: ipv4.static.route.add.unique.ptc0 | H11: 1200105 | I11: LEVEL0 | J11: NE1_link0 | L11: 网元正常启动 | M11: 1、添加静态路由，目的网络地址掩码长度相同，下一跳不相同【check1】 2、添加静态路由，目的网络地址掩码长度相同，下一跳相同【check2】 3、添加静态路由，目的网络地址相同，掩码长度不相同，下一跳相同【check1】 | N11: 【check1】配置成功，使用restful查询静态路由与下发的配置相同。使用etcd查询/vnf-agent/vpp1/config/linux/l3/v2/routes/<dip>/<掩码>/preference/<优先级>，查询的值与配置的值相同 【check2】配置失败。使用etcd查询/vnf-agent/vpp1/config/linux/l3/v2/routes/<dip>/<掩码>/preference/<优先级>，查询添加失败的路由不存在 | O11: NGFW_V60R1C00 | P11: J1900,C236,EP | S11: 配置测试 | T11: 是
F12: 验证修改静态路由时配置下一跳有效值和无效值测试 | G12: ipv4.static.route.modify.ptc0 | H12: 1200106 | I12: LEVEL0 | J12: NE1_link0 | L12: 网元正常启动 | M12: 1、添加一条静态路由，并获取路由ID 2、使用/api/v1/route修改该静态路由时，配置下一跳为1.0.0.0,其他参数为任意有效值查询静态路由【check1】 3、使用/api/v1/route修改该静态路由时，配置下一跳为223.255.255.255,其他参数为任意有效值查询静态路由【check1】 4、使用/api/v1/route修改该静态路由时，配置下一跳为(1-126].[0-255].[0-255].[0-255],其他参数为任意有效值查询静态路由【check1】 5、使用/api/v1/route修改该静态路由时，配置下一跳为[128-223].[0-255].[0-255].[0-255],其他参数为任意有效值查询静态路由【check1】 6、修改该静态路由时，配置下一跳为0.[0-255].[0-255].[0-255],其他参数为任意有效值查询静态路由【check2】 7、修改该静态路由时，配置下一跳为224.[0-255].[0-255].[0-255],其他参数为任意有效值查询静态路由【check2】 8、修改该静态路由时，配置下一跳为空,其他参数为任意有效值查询静态路由【check2】 9、修改该静态路由时，配置下一跳为超长字符串,其他参数为任意有效值查询静态路由【check2】 10、修改该静态路由时，配置下一跳为3段点分十进制,其他参数为任意有效值查询静态路由【check2】 11、修改该静态路由时，配置下一跳为5段点分十进制,其他参数为任意有效值查询静态路由【check2】 12、修改该静态路由时，配置下一跳为点分号非".",其他参数为任意有效值查询静态路由【check2】 13、修改该静态路由时，配置下一跳为127.[0-255].[0-255].[0-255],其他参数为任意有效值查询静态路由【check2】 14、修改该静态路由时，配置下一跳为任意接口的IP,其他参数为任意有效值查询静态路由【check2】 | N12: 【check1】配置成功，使用restful查询静态路由与下发的配置相同。使用etcd查询/vnf-agent/vpp1/config/linux/l3/v2/routes/<dip>/<掩码>/preference/<优先级>，查询的值与配置的值相同 【check2】配置失败，网元无异常。使用etcd查询/vnf-agent/vpp1/config/linux/l3/v2/routes/<dip>/<掩码>/preference/<优先级>，查询添加失败的路由不存在 | O12: NGFW_V60R1C00 | P12: J1900,C236,EP | S12: 配置测试 | T12: 是
F13: 验证修改静态路由时配置权重有效值和无效值测试 | G13: ipv4.static.route.modify.ptc1 | H13: 1200107 | I13: LEVEL0 | J13: NE1_link0 | L13: 网元正常启动 | M13: 1、添加一条静态路由，并获取路由ID 2、使用/api/v1/route修改该静态路由时，配置权重为1.0,其他参数为任意有效值查询静态路由【check1】 3、使用/api/v1/route修改该静态路由时，配置权重为(0-255)间任意值,其他参数为任意有效值查询静态路由【check1】 4、使用/api/v1/route修改该静态路由时，配置权重为255.0,其他参数为任意有效值查询静态路由【check1】 5、使用/api/v1/route修改该静态路由时，配置权重为空,其他参数为任意有效值查询静态路由【check1】 6、修改该静态路由时，配置权重为0.0,其他参数为任意有效值查询静态路由【check2】 7、修改该静态路由时，配置权重为256.0,其他参数为任意有效值查询静态路由【check2】 8、修改该静态路由时，配置权重为字符串,其他参数为任意有效值查询静态路由【check2】 9、修改该静态路由时，配置权重为超长字符串,其他参数为任意有效值查询静态路由【check2】 | N13: 【check1】配置成功，使用restful查询静态路由与下发的配置相同。使用etcd查询/vnf-agent/vpp1/config/linux/l3/v2/routes/<dip>/<掩码>/preference/<优先级>，查询的值与配置的值相同 【check2】配置失败，网元无异常。使用etcd查询/vnf-agent/vpp1/config/linux/l3/v2/routes/<dip>/<掩码>/preference/<优先级>，查询添加失败的路由不存在 | O13: NGFW_V60R1C00 | P13: J1900,C236,EP | S13: 配置测试 | T13: 是
F14: 验证修改静态路由时配置优先级有效值和无效值测试 | G14: ipv4.static.route.modify.ptc2 | H14: 1200108 | I14: LEVEL0 | J14: NE1_link0 | L14: 网元正常启动 | M14: 1、添加一条静态路由，并获取路由ID 2、使用/api/v1/route修改该静态路由时，配置优先级为1.0,其他参数为任意有效值查询静态路由【check1】 3、使用/api/v1/route修改该静态路由时，配置优先级为(1-255)间任意值,其他参数为任意有效值查询静态路由【check1】 4、使用/api/v1/route修改该静态路由时，配置优先级为255.0,其他参数为任意有效值查询静态路由【check1】 5、使用/api/v1/route修改该静态路由时，配置优先级为空,其他参数为任意有效值查询静态路由【check1】 6、修改该静态路由时，配置优先级为0.0,其他参数为任意有效值查询静态路由【check2】 7、修改该静态路由时，配置优先级为256.0,其他参数为任意有效值查询静态路由【check2】 8、修改该静态路由时，配置优先级为字符串,其他参数为任意有效值查询静态路由【check2】 9、修改该静态路由时，配置优先级为超长字符串,其他参数为任意有效值查询静态路由【check2】 | N14: 【check1】配置成功，使用restful查询静态路由与下发的配置相同。使用etcd查询/vnf-agent/vpp1/config/linux/l3/v2/routes/<dip>/<掩码>/preference/<优先级>，查询的值与配置的值相同 【check2】配置失败，网元无异常。使用etcd查询/vnf-agent/vpp1/config/linux/l3/v2/routes/<dip>/<掩码>/preference/<优先级>，查询添加失败的路由不存在 | O14: NGFW_V60R1C00 | P14: J1900,C236,EP | S14: 配置测试 | T14: 是
F15: 验证修改静态路由不支持修改的字段测试 | G15: ipv4.static.route.invalid.modify.ptc0 | H15: 1200109 | I15: LEVEL0 | J15: NE1_link0 | L15: 网元正常启动 | M15: 1、添加一条静态路由，并获取路由ID 2、使用/api/v1/route修改该静态路由的目的IP，观察路由【check1】 3、使用/api/v1/route修改该静态路由的掩码长度，观察路由【check1】 4、使用/api/v1/route修改路由时使用不存在的路由ID【check2】 | N15: 【check1】配置失败，提示信息正确，使用restful查询静态路由与下发的配置相同。使用etcd查询/vnf-agent/vpp1/config/linux/l3/v2/routes/<dip>/<掩码>/preference/<优先级>，查询的值与配置的值相同 【check2】配置失败，提示信息正确。 | O15: NGFW_V60R1C00 | P15: J1900,C236,EP | S15: 配置测试 | T15: 是
F16: 验证查询静态路由分页查询功能 | G16: ipv4.static.route.query.page.ptc0 | H16: 1200110 | I16: LEVEL0 | J16: NE1_link0 | L16: 网元正常启动 | M16: 1、选取任意有效的分页size为s，网元中不存在任何静态路由时使用接口/api/v1/route?page=1&size=<s>&is_ip6=false查询静态路由。【check1】 2、配置1条静态路由后使用restful查询接口查询静态路由。【check2】 3、添加至少2倍s条静态路由，使用查询接口查询第一页（page=1）静态路由。【check3】 4、使用静态路由查询接口查询最后一页静态路由。【check4】 5、使用静态路由查询接口查询中间任意页静态路由。【check3】 | N16: 【check1】返回值为空 【check2】查询结果与配置的值相同 【check3】返回s条静态路由，路由信息正确 【check4】返回路由条数为配置的路由条数除以s所得的余数，路由信息正确 | O16: NGFW_V60R1C00 | P16: J1900,C236,EP | S16: 配置测试 | T16: 是
F17: 验证查询静态路由分页大小典型值测试 | G17: ipv4.static.route.query.size.ptc0 | H17: 1200111 | I17: LEVEL0 | J17: NE1_link0 | L17: 网元正常启动 | M17: 1、配置大于40条静态路由 2、使用静态路由典型分页值10查询静态路由1到4页任意值的静态路由/api/v1/route?page=[1-4]&size=10&is_ip6=false查询静态路由。【check1】 3、使用静态路由典型分页值20查询静态路由1到2页任意值的静态路由。【check2】 4、使用静态路由典型分页值30查询静态路由1页任意值的静态路由。【check2】 5、使用静态路由典型分页值40查询静态路由1页任意值的静态路由。【check2】 | N17: 【check1】返回路由的条数与分页size相同，且信息正确 【check2】返回所有的路由，且信息正确 | O17: NGFW_V60R1C00 | P17: J1900,C236,EP | S17: 配置测试 | T17: 是
F18: 验证查询静态路由页数和分页大小异常值 | G18: ipv4.static.route.query.abnormal.ptc0 | H18: 1200112 | I18: LEVEL0 | J18: NE1_link0 | L18: 网元正常启动 | M18: 1、配置任意条数的静态路由 2、使用静态路由查询接口查询0页分页大小为0的静态路由。/api/v1/route?page=0&size=0&is_ip6=false.【check1】 3、查询静态路由page为最大值，size为最大值的。【check2】 4、查询静态路由page大于最大值【check2】 5、查询静态路由size大于最大值【check2】 6、查询静态路由page和size均为异常字符串【check2】 | N18: 【check1】返回所有的路由，且信息正确 【check2】返回当前路由条数，条数正确 【check3】返回第一页的静态路由信息 | O18: NGFW_V60R1C00 | P18: J1900,C236,EP | S18: 配置测试 | T18: 是
F19: 验证静态路由删除和批量删除功能 | G19: ipv4.static.route.delete.ptc0 | H19: 1200113 | I19: LEVEL0 | J19: NE1_link0 | L19: 网元正常启动 | M19: 1、配置大于40条静态路由 2、使用静态路由典型分页值10查询静态路由1到4页任意值的静态路由/api/v1/route?page=[1-4]&size=10&is_ip6=false查询静态路由。【check1】 3、使用静态路由典型分页值20查询静态路由1到2页任意值的+F96静态路由。【check2】 4、使用静态路由典型分页值30查询静态路由1页任意值的静态路由。【check2】 5、使用静态路由典型分页值40查询静态路由1页任意值的静态路由。【check2】 | N19: 【check1】删除成功，静态路由配置表中配置被删除。 【check2】使用restful查询路由，对应的路由不存在 【check3】使用etcd查询路由，路由被删除 【check4】删除失败，提示信息正确。查询静态路由表与删除前完全一致（无路由备误删）。 【check5】返回删除失败，其中有效的ID被删除。查看静态路由配置中不包含在有效ID中的路由不会被删除 | O19: NGFW_V60R1C00 | P19: J1900,C236,EP | S19: 配置测试 | T19: 是
... F22: 验证配置静态路由默认值 | G22: ipv4.static.route.default.ptc0 | H22: 1200116 | I22: LEVEL0 | J22: NE1_link0 | L22: 1、网元正常启动 | M22: 1、添加静态路由，权重和优先级为空。 2、检查静态路由表，查看权重和优先级。【check1】【check2】 3、配置接口IP地址。查看直连路由。【check3】 | N22: 【check1】权重默认值为1(当前存在问题)。etcd查看路由的权重默认值为1 【check2】优先级默认值为60(参考华为实现)。etcd查看路由的优先级默认值为60 【check3】直连路由默认优先级为0，cost为0。etcd查看路由的优先级默认值为0，权重默认值为1 | O22: NGFW_V60R1C00 | P22: J1900,C236,EP | S22: 配置测试 | T22: 是
D23: 路由维护
E24: 静态路由
F25: 添加静态路由匹配物理接口状态为UP时直接生成路由转发表 | G25: ipv4.static.fib.add.p1.ptc0 | H25: 1201101 | I25: LEVEL2 | J25: NE1_ins | L25: 网元正常启动 | M25: 1、配置物理接口的IP地址与下一跳同网段，该接口的状态为UP 2、添加静态路由，目的网段为0.0.0.0/0，权重为0，优先级为1，下一跳为与1.0.0.0【check1】 3、查看路由转发表【check2】 | N25: 【check1】配置成功 【check2】路由转发表生成该路由 | O25: NGFW_V60R1C00 | P25: J1900,C236,EP | R25: 预测试 | S25: 功能测试 | T25: 是
F26: 添加静态路由匹配BVI接口状态为UP时直接生成路由转发表 | G26: ipv4.static.fib.add.p1.ptc1 | H26: 1201102 | I26: LEVEL2 | J26: NE1_ins | L26: 网元正常启动 | M26: 1、配置BVI接口的IP地址与下一跳同网段，该接口的状态为UP 2、添加静态路由，目的网段为,[1-126].[0-255].[0-255].[0-255]/[1-31]，权重为255，优先级为255，下一跳为与223.255.255.255【check1】 3、查看路由转发表【check2】 | N26: 【check1】配置成功 【check2】路由转发表生成该路由 | O26: NGFW_V60R1C00 | P26: J1900,C236,EP | S26: 功能测试 | T26: 是
F27: 添加静态路由再修改状态为UP的聚合接口IP匹配静态路由后生成路由转发表 | G27: ipv4.static.fib.add.p2.ptc0 | H27: 1201103 | I27: LEVEL2 | J27: NE1_ins | L27: 网元正常启动 | M27: 1、添加静态路由，目的网段为223.255.255.255/32，权重为(0-255)间任意值，优先级为(1-255)间任意值，下一跳为与(1-126].[0-255].[0-255].[0-255]【check1】 2、配置状态为UP的聚合接口的IP地址与静态路由下一跳在相同网段【check1】 3、查看路由转发表【check2】 | N27: 【check1】配置成功 【check2】路由转发表生成该路由 | O27: NGFW_V60R1C00 | P27: J1900,C236,EP | S27: 功能测试 | T27: 是
F28: 添加静态路由再修改状态为UP的L3子接口IP匹配静态路由后生成路由转发表 | G28: ipv4.static.fib.add.p2.ptc1 | H28: 1201104 | I28: LEVEL2 | J28: NE1_ins | L28: 网元正常启动 | M28: 1、添加静态路由，目的网段为[128-223).[0-255].[0-255].[0-255]/[1-31]，权重为空，优先级为空，下一跳为与[128-223].[0-255].[0-255].[0-255]【check1】 2、配置状态为UP的L3子接口的IP地址与静态路由下一跳在相同网段【check1】 3、查看路由转发表【check2】 | N28: 【check1】配置成功 【check2】路由转发表生成该路由 | O28: NGFW_V60R1C00 | P28: J1900,C236,EP | S28: 功能测试 | T28: 是
F29: 添加静态路由匹配物理接口状态由Down到UP后生成路由转发表 | G29: ipv4.static.fib.add.p3.ptc0 | H29: 1201105 | I29: LEVEL2 | J29: NE1_ins | L29: 网元正常启动 | M29: 1、配置物理接口的IP地址与下一跳同网段，该接口的状态为Down 2、添加静态路由，目的网段为0.0.0.0/0，权重为0，优先级为1，下一跳为与1.0.0.0【check1】 3、查看路由转发表【check2】 4、构造接口状态为UP，查看路由转发表【check3】 | N29: 【check1】配置成功 【check2】路由转发表中不生成该路由 【check3】路由转发表生成该路由 | O29: NGFW_V60R1C00 | P29: J1900,C236,EP | S29: 功能测试 | T29: 是
F30: 添加静态路由匹配聚合接口状态由Down到UP后生成路由转发表 | G30: ipv4.static.fib.add.p3.ptc1 | H30: 1201106 | I30: LEVEL2 | J30: NE1_ins | L30: 网元正常启动 | M30: 1、配置聚合接口的IP地址与下一跳同网段，该接口的状态为Down 2、添加静态路由，目的网段为,[1-126].[0-255].[0-255].[0-255]/[1-31]，权重为255，优先级为255，下一跳为与223.255.255.255【check1】 3、查看路由转发表【check2】 4、构造接口状态为UP，查看路由转发表【check3】 | N30: 【check1】配置成功 【check2】路由转发表中不生成该路由 【check3】路由转发表生成该路由 | O30: NGFW_V60R1C00 | P30: J1900,C236,EP | S30: 功能测试 | T30: 是
F31: 添加静态路由再修改BVI接口IP匹配静态路由后状态由Down到UP后生成转发表 | G31: ipv4.static.fib.add.p4.ptc0 | H31: 1201107 | I31: LEVEL2 | J31: NE1_ins | L31: 网元正常启动 | M31: 1、添加静态路由，目的网段为223.255.255.255/32，权重为(0-255)间任意值，优先级为(1-255)间任意值，下一跳为与(1-126].[0-255].[0-255].[0-255]【check1】 2、配置状态为Down的BVI接口的IP地址与静态路由下一跳在相同网段【check1】 3、查看路由转发表【check2】 4、构造接口状态为UP，查看路由转发表【check3】 | N31: 【check1】配置成功 【check2】路由转发表中不生成该路由 【check3】路由转发表生成该路由 | O31: NGFW_V60R1C00 | P31: J1900,C236,EP | S31: 功能测试 | T31: 是
F32: 添加静态路由再修改L3子接口IP匹配静态路由后状态由Down到UP后生成转发表 | G32: ipv4.static.fib.add.p4.ptc1 | H32: 1201108 | I32: LEVEL2 | J32: NE1_ins | L32: 网元正常启动 | M32: 1、添加静态路由，目的网段为[128-223).[0-255].[0-255].[0-255]/[1-31]，权重为空，优先级为空，下一跳为与[128-223].[0-255].[0-255].[0-255]【check1】 2、配置状态为Down的L3子接口的IP地址与静态路由下一跳在相同网段【check1】 3、查看路由转发表【check2】 4、构造接口状态为UP，查看路由转发表【check3】 | N32: 【check1】配置成功 【check2】路由转发表中不生成该路由 【check3】路由转发表生成该路由 | O32: NGFW_V60R1C00 | P32: J1900,C236,EP | S32: 功能测试 | T32: 是
F33: 验证修改静态路由下一跳与所有接口IP不在相同网段后静态路由失效 | G33: ipv4.static.fib.delete.0 | H33: 1201109 | I33: LEVEL2 | J33: NE1_ins | L33: 网元正常启动 | M33: 1、配置物理接口或聚合口或者BVI接口或者L3子接口的IP地址 2、配置静态路由的下一跳与该IP地址在相同网段。【check1】 3、修改静态路由下一跳与所有接口IP不在相同网段后观察路由转发表【check2】 | N33: 【check1】配置成功，路由转发表中生成该路由 【check2】路由转发表中该路由消失 | O33: NGFW_V60R1C00 | P33: J1900,C236,EP | S33: 功能测试 | T33: 是
F34: 验证修改接口IP与静态路由不在相同网段后静态路由失效 | G34: ipv4.static.fib.delete.1 | H34: 1201110 | I34: LEVEL2 | J34: NE1_ins | L34: 网元正常启动 | M34: 1、配置物理接口或聚合口或者BVI接口或者L3子接口的IP地址 2、配置静态路由的下一跳与该IP地址在相同网段。【check1】 3、修改接口IP与静态路由不在相同网段后观察路由转发表【check2】 | N34: 【check1】配置成功，路由转发表中生成该路由 【check2】路由转发表中该路由消失 | O34: NGFW_V60R1C00 | P34: J1900,C236,EP | S34: 功能测试 | T34: 是
F35: 验证禁用路由出接口后静态路由失效 | G35: ipv4.static.fib.delete.2 | H35: 1201111 | I35: LEVEL2 | J35: NE1_ins | L35: 网元正常启动 | M35: 1、配置物理接口或聚合口或者BVI接口或者L3子接口的IP地址 2、配置静态路由的下一跳与该IP地址在相同网段。【check1】 3、禁用路由出接口后观察路由转发表【check2】 | N35: 【check1】配置成功，路由转发表中生成该路由 【check2】路由转发表中该路由消失 | O35: NGFW_V60R1C00 | P35: J1900,C236,EP | S35: 功能测试 | T35: 是
F36: 验证拔掉路由出接口网线后静态路由失效 | G36: ipv4.static.fib.delete.3 | H36: 1201112 | I36: LEVEL2 | J36: NE1_ins | L36: 网元正常启动 | M36: 1、配置物理接口或聚合口或者BVI接口或者L3子接口的IP地址 2、配置静态路由的下一跳与该IP地址在相同网段。【check1】 3、拔掉路由出接口网线后观察路由转发表【check2】 | N36: 【check1】配置成功，路由转发表中生成该路由 【check2】路由转发表中该路由消失 | O36: NGFW_V60R1C00 | P36: J1900,C236,EP | S36: 功能测试 | T36: 是
F37: 验证删除静态路由后静态路由失效 | G37: ipv4.static.fib.delete.4 | H37: 1201113 | I37: LEVEL2 | J37: NE1_ins | L37: 网元正常启动 | M37: 1、配置物理接口或聚合口或者BVI接口或者L3子接口的IP地址 2、配置静态路由的下一跳与该IP地址在相同网段。【check1】 3、删除静态路由后观察路由转发表【check2】 | N37: 【check1】配置成功，路由转发表中生成该路由 【check2】路由转发表中该路由消失 | O37: NGFW_V60R1C00 | P37: J1900,C236,EP | S37: 功能测试 | T37: 是
... F52: 验证配置静态路由存库功能 | G52: ipv4.static.cfg.recover.ptc0 | H52: 1201128 | I52: LEVEL4 | J52: NE1_link4_ins | L52: 1、网元正常启动 | M52: 1、添加,修改,删除静态路由后，快速掉电设备。设备重启后，查看配置和路由表【check1】 | N52: 【check1】配置与掉电前相同，路由转发表表项正确。 | O52: NGFW_V60R1C00 | P52: J1900,C236,EP | S52: 可靠性测试 | T52: 否
E53: 直连路由
F54: 验证物理接口的IP地址生成直连路由功能 | G54: ipv4.direct.route.fib.ptc0 | H54: 1201201 | I54: LEVEL2 | J54: NE1_ins | L54: 网元正常启动 | M54: 1、配置物理接口为路由模式 2、配置接口的IP地址为128.0.0.1/2，并观察路由转发表【check1】 3、配置接口的IP地址为首段为(1~126]的任意有效值，并观察路由转发表【check1】 4、构造接口状态为Down，观察路由转发表【check2】 | N54: 【check1】配置成功，路由转发表中生成接口IP所在网段的直连路由 【check2】接口IP生成的直连路由消失 | O54: NGFW_V60R1C00 | P54: J1900,C236,EP | R54: 预测试 | S54: 功能测试 | T54: 是
F55: 验证聚合接口的IP地址生成直连路由功能 | G55: ipv4.direct.route.fib.ptc1 | H55: 1201202 | I55: LEVEL2 | J55: NE1_link4_ins | L55: 网元正常启动 | M55: 1、配置聚合接口为路由模式 2、配置接口的IP地址为233.255.255.254/30，并观察路由转发表【check1】 3、构造接口状态为Down，观察路由转发表【check2】 | N55: 【check1】配置成功，路由转发表中生成接口IP所在网段的直连路由 【check2】接口IP生成的直连路由消失 | O55: NGFW_V60R1C00 | P55: J1900,C236,EP | S55: 功能测试 | T55: 是
F56: 验证L3子接口的IP地址生成直连路由功能 | G56: ipv4.direct.route.fib.ptc2 | H56: 1201203 | I56: LEVEL2 | J56: NE1_ins | L56: 网元正常启动 | M56: 1、配置L3子接口为路由模式 2、配置接口的IP地址为1.0.0.1/30，并观察路由转发表【check1】 3、构造接口状态为Down，观察路由转发表【check2】 | N56: 【check1】配置成功，路由转发表中生成接口IP所在网段的直连路由 【check2】接口IP生成的直连路由消失 | O56: NGFW_V60R1C00 | P56: J1900,C236,EP | S56: 功能测试 | T56: 是
...

Sheet 附录1
A1: 统计信息
A2: 用例级别 | B2: 目标占比 | C2: 实际占比
A3: LEVEL0~1 | B3: <15% | C3: =C$9+C$10 -> 0.14678899
A4: LEVEL2~3 | B4: >40% | C4: =C$11+C$12 -> 0.53211009
A5: LEVEL0~3 | B5: >60% | C5: =C$9+C$10+C$11+C$12 -> 0.67889908
A6: 可自动化率 | B6: =E9/SUM(E9:E10) -> 0.67889908
A7: 详细数据
A8: 用例级别 | B8: 数量 | C8: 占比 | D8: 是否自动化 | E8: 数量
A9: LEVEL0 | B9: =COUNTIF(用例全集!$I:$I,A9) -> 14 | C9: =B9/SUM(B$9:B$15) -> 0.12844037 | D9: 是 | E9: =COUNTIF(用例全集!$T:$T,D9) -> 74
A10: LEVEL1 | B10: =COUNTIF(用例全集!$I:$I,A10) -> 2 | C10: =B10/SUM(B$9:B$15) -> 0.018348624 | D10: 否 | E10: =COUNTIF(用例全集!$T:$T,D10) -> 35
A11: LEVEL2 | B11: =COUNTIF(用例全集!$I:$I,A11) -> 52 | C11: =B11/SUM(B$9:B$15) -> 0.47706422
A12: LEVEL3 | B12: =COUNTIF(用例全集!$I:$I,A12) -> 6 | C12: =B12/SUM(B$9:B$15) -> 0.055045872
A13: LEVEL4 | B13: =COUNTIF(用例全集!$I:$I,A13) -> 28 | C13: =B13/SUM(B$9:B$15) -> 0.25688073
A14: LEVEL5 | B14: =COUNTIF(用例全集!$I:$I,A14) -> 6 | C14: =B14/SUM(B$9:B$15) -> 0.055045872
A15: LEVEL6 | B15: =COUNTIF(用例全集!$I:$I,A15) -> 1 | C15: =B15/SUM(B$9:B$15) -> 0.0091743119
A16: 总数 | B16: =SUM(B9:B15) -> 109
A19: 用例基线时间点
A20: TR5基线一次 | B20: TR6基线一次
A22: 字段填写说明
A23: 用例编号 | B23: 使用1到4级目录加三位数字，例如SrvQuality.Qos.Classfy.DiffServ001
A24: 用例级别 | B24: 使用LEVEL0~LEVEL6级，定义说明见下表
B25: 用例级别 | C25: 层级描述 | D25: 备注 | F25: 统计说明
B26: LEVEL0 | C26: 配置测试 | D26: 包含配置测试、配置容错测试 | F26: 1、基本用例Level0~Level3占比总用例60%以上；Level0~Level1占总用例不超过15%，Level2~Level3占总用例至少40% 2、Level0、Level2级别的用例可以做自动化用例；Level1、Level3级别的用例争取做自动化
B27: LEVEL1 | C27: 配置可靠性测试 | D27: 包含配置容限测试、Oplog
B28: LEVEL2 | C28: 基本功能测试 | D28: 客户常用功能和常用告警性能
B29: LEVEL3 | C29: 扩展功能测试 | D29: 客户不常用的功能和不常用告警性能
B30: LEVEL4 | C30: 特性可靠性 | D30: 包含单特性的可靠性测试用例。包括反复增删单特性配置、复位重启、拔插单板、网线、主备切换等
B31: LEVEL5 | C31: 特性耦合测试 | D31: 包含两特性耦合和多特性耦合测试用例
B32: LEVEL6 | C32: 特性升级 | D32: 单特性的升级测试用例，包括升级前后配置检查、升级后观察业务、增删配置等
A33: 组网描述 | B33: 必须是用英文的逗号分隔。例如Update01,Update02
A34: 组网约束 | B34: 按实际情况填写
A35: 预置条件 | B35: 按实际情况填写
A36: 测试步骤 | B36: 通常一个用例不超过7步
A37: 预期结果 | B37: 使用check点的方式填写
A38: 适用版本 | B38: 必须以英文逗号分隔,必须使用统一的名称:V1R1C00,V1R1C01
A39: 设备类型* | B39: 必须以英文逗号分隔,J1900,C236,EP
A40: 单板类型 | B40: 必须以英文逗号分隔,
A41: 关键词 | B41: 必须以逗号分隔，公共的关键字必须一致，新增关键字找用例管理员申请
A42: 测试类型* | B42: LEVEL0,LEVEL1-->配置测试；LEVEL2,LEVEL3-->功能测试；LEVEL4-->可靠性测试；LEVL5-->耦合测试；LEVEL6-->升级测试
A43: 是否自动化* | B43: "是"或者"否"
...
